Workbook

Sheet Overview
A2: Aim
A3: Investigate access to safe and affordable drinking water.
A5: Questions
A6: 1 | B6: How frequently was water access data collected across countries?
A7: 2 | B7: How does the annual rate of change in water access differ between rural and urban populations?
A8: 3 | B8: How does the rate of change in water access vary across regions and population sizes?
A10: Key Findings
A11: 1 | B11: Data was collected between 2015 and 2020 with an average year difference of 4.8, with most countries having a 5 year difference and a few between 1 and 4. Different collection periods demand use of annual rates of change to compare countries fairly.
A12: 2 | B12: Rural water access improved faster than urban access, averaging 0.48 against 0.15 percentage points per year. The higher rural rate reflects that rural areas start at a lower base.
A13: 3 | B13: Sub-Saharan Africa improved fastest at 0.56 percentage points per year, while Europe & Central Asia and North America barely changed. These regions are already near full access, so a low rate reflects little room to improve rather than poor performance.
A15: Data Dictionary
A16: pop_n | B16: The national population size estimate, in thousands.
A17: pop_u | B17: The urban population share estimate in percentage points (%).
A18: pop_r | B18: The rural population share estimate in percentage points (%).
A19: ARC | B19: Annual rate of change. This is the yearly change of access to water in percentage points.
A20: ARC_n | B20: The national Annual Rate of Change.
A21: ARC_u | B21: The urban Annual Rate of Change.
A22: ARC_r | B22: The rural Annual Rate of Change.
A23: wat_unimp_n | B23: The estimated national share of people with unimproved service (%).
A24: wat_unimp_u | B24: The estimated urban share of people with unimproved service (%).
A25: wat_unimp_r | B25: The estimated rural share of people with unimproved service (%).
A26: wat_sur_n | B26: The estimated national share of people with surface service (%).
A27: wat_sur_u | B27: The estimated urban share of people with surface service (%).
... A31: wat_bas_r | B31: The estimated rural share of people with at least basic service (%).

Sheet Estimates of the use of water (
A1: name | B1: region | C1: year | D1: year_difference | E1: ARC_n | F1: pop_n | G1: pop_u | H1: wat_bas_n | I1: wat base_n_ rounded | J1: wat base n_access | K1: wat_lim_n | L1: wat_unimp_n | M1: wat_sur_n | N1: wat_bas_r | O1: wat _bas_r_round | P1: wat_bas_r_access | Q1: Arc R | R1: wat_lim_r | S1: wat_unimp_r | T1: wat_sur_r | U1: wat_bas_u | V1: wat_bas_u_round | W1: wat_bas_u_access | X1: Arc U | Y1: wat_lim_u | Z1: wat_unimp_u | AA1: wat_sur_u | AB1: ARC difference
A2: Afghanistan | B2: =VLOOKUP(A2,Regions!A:B,2,0) -> South Asia | C2: 2015 | D2: =IF(A3=A2,ABS(C3-C2),"") -> 5 | E2: =IFERROR(IF(A3=A2,((H2-H3)/(C2-C3)), ""), "null") -> 2.7503265 | F2: 34413.602 | G2: 24.802999 | H2: 61.339781 | I2: =IFERROR(ROUND(H2,0),"null") -> 61 | J2: =IF(AND(A3=A2,I2=100,I3=100),"full access", " ") | K2: 3.5111995 | L2: 22.168784 | M2: 12.980236 | N2: 52.988502 | O2: =IFERROR(ROUND(N2,0),"null") -> 53 | P2: =IF(AND(A2=A3,O2=100,O3=100),"full access"," ") | Q2: =IFERROR(IF(A3=A2,((N2-N3)/(C2-C3)),""),"null") -> 2.6678826 | R2: 3.8611366 | S2: 26.553268 | T2: 16.597094 | U2: 86.658941 | V2: =IFERROR(ROUND(U2,0),"null") -> 87 | W2: =IF(AND(A2=A3,V2=100,V3=100),"full access","") | X2: =IFERROR(IF(A3=A2,((U2-U3)/(C2-C3)),""),"null") -> 2.6682119 | Y2: 2.4502706 | Z2: 8.8760357 | AA2: 2.014753 | AB2: =IFERROR(IF(A3=A2, Q2-X2, ""), "null") -> -0.000329218
A3: Afghanistan | B3: =VLOOKUP(A3,Regions!A:B,2,0) -> South Asia | C3: 2020 | D3: =IF(A4=A3,ABS(C4-C3),"") | E3: =IFERROR(IF(A4=A3,((H3-H4)/(C3-C4)), ""), "null") | F3: 38928.34 | G3: 26.025999 | H3: 75.091413 | I3: =IFERROR(ROUND(H3,0),"null") -> 75 | J3: =IF(AND(A4=A3,I3=100,I4=100),"full access", " ") | K3: 1.4475417 | L3: 14.560263 | M3: 8.9007822 | N3: 66.327915 | O3: =IFERROR(ROUND(N3,0),"null") -> 66 | P3: =IF(AND(A3=A4,O3=100,O4=100),"full access"," ") | Q3: =IFERROR(IF(A4=A3,((N3-N4)/(C3-C4)),""),"null") | R3: 1.9568249 | S3: 19.682949 | T3: 12.032311 | U3: 100 | V3: =IFERROR(ROUND(U3,0),"null") -> 100 | W3: =IF(AND(A3=A4,V3=100,V4=100),"full access","") | X3: =IFERROR(IF(A4=A3,((U3-U4)/(C3-C4)),""),"null") | Y3: 0 | Z3: 0 | AA3: 0 | AB3: =IFERROR(IF(A4=A3, Q3-X3, ""), "null")
A4: Albania | B4: =VLOOKUP(A4,Regions!A:B,2,0) -> Europe & Central Asia | C4: 2015 | D4: =IF(A5=A4,ABS(C5-C4),"") -> 5 | E4: =IFERROR(IF(A5=A4,((H4-H5)/(C4-C5)), ""), "null") -> 0.3347427 | F4: 2890.5239 | G4: 57.433998 | H4: 93.394325 | I4: =IFERROR(ROUND(H4,0),"null") -> 93 | J4: =IF(AND(A5=A4,I4=100,I5=100),"full access", " ") | K4: 3.6263837 | L4: 2.979291 | M4: 0 | N4: 90.627275 | O4: =IFERROR(ROUND(N4,0),"null") -> 91 | P4: =IF(AND(A4=A5,O4=100,O5=100),"full access"," ") | Q4: =IFERROR(IF(A5=A4,((N4-N5)/(C4-C5)),""),"null") -> 0.69281669 | R4: 5.2631726 | S4: 4.1095527 | T4: 0 | U4: 95.445067 | V4: =IFERROR(ROUND(U4,0),"null") -> 95 | W4: =IF(AND(A4=A5,V4=100,V5=100),"full access","") | X4: =IFERROR(IF(A5=A4,((U4-U5)/(C4-C5)),""),"null") -> 0.043748432 | Y4: 2.4133118 | Z4: 2.1416212 | AA4: 0 | AB4: =IFERROR(IF(A5=A4, Q4-X4, ""), "null") -> 0.64906826
A5: Albania | B5: =VLOOKUP(A5,Regions!A:B,2,0) -> Europe & Central Asia | C5: 2020 | D5: =IF(A6=A5,ABS(C6-C5),"") | E5: =IFERROR(IF(A6=A5,((H5-H6)/(C5-C6)), ""), "null") | F5: 2877.8 | G5: 62.112 | H5: 95.068039 | I5: =IFERROR(ROUND(H5,0),"null") -> 95 | J5: =IF(AND(A6=A5,I5=100,I6=100),"full access", " ") | K5: 1.8846561 | L5: 3.0473051 | M5: 0 | N5: 94.091358 | O5: =IFERROR(ROUND(N5,0),"null") -> 94 | P5: =IF(AND(A5=A6,O5=100,O6=100),"full access"," ") | Q5: =IFERROR(IF(A6=A5,((N5-N6)/(C5-C6)),""),"null") | R5: 2.305265 | S5: 3.603377 | T5: 0 | U5: 95.663809 | V5: =IFERROR(ROUND(U5,0),"null") -> 96 | W5: =IF(AND(A5=A6,V5=100,V6=100),"full access","") | X5: =IFERROR(IF(A6=A5,((U5-U6)/(C5-C6)),""),"null") | Y5: 1.6280868 | Z5: 2.7081041 | AA5: 0 | AB5: =IFERROR(IF(A6=A5, Q5-X5, ""), "null")
A6: Algeria | B6: =VLOOKUP(A6,Regions!A:B,2,0) -> Middle East & North Africa | C6: 2015 | D6: =IF(A7=A6,ABS(C7-C6),"") -> 5 | E6: =IFERROR(IF(A7=A6,((H6-H7)/(C6-C7)), ""), "null") -> 0.20555369 | F6: 39728.02 | G6: 70.848 | H6: 93.409562 | I6: =IFERROR(ROUND(H6,0),"null") -> 93 | J6: =IF(AND(A7=A6,I6=100,I7=100),"full access", " ") | K6: 5.1577809 | L6: 1.2754647 | M6: 0.15719289 | N6: 88.352707 | O6: =IFERROR(ROUND(N6,0),"null") -> 88 | P6: =IF(AND(A6=A7,O6=100,O7=100),"full access"," ") | Q6: =IFERROR(IF(A7=A6,((N6-N7)/(C6-C7)),""),"null") -> 0.33696621 | R6: 8.6857531 | S6: 2.5804318 | T6: 0.38110822 | U6: 95.490315 | V6: =IFERROR(ROUND(U6,0),"null") -> 95 | W6: =IF(AND(A6=A7,V6=100,V7=100),"full access","") | X6: =IFERROR(IF(A7=A6,((U6-U7)/(C6-C7)),""),"null") -> 0.10288423 | Y6: 3.7061173 | Z6: 0.73851009 | AA6: 0.065057898 | AB6: =IFERROR(IF(A7=A6, Q6-X6, ""), "null") -> 0.23408198
A7: Algeria | B7: =VLOOKUP(A7,Regions!A:B,2,0) -> Middle East & North Africa | C7: 2020 | D7: =IF(A8=A7,ABS(C8-C7),"") | E7: =IFERROR(IF(A8=A7,((H7-H8)/(C7-C8)), ""), "null") | F7: 43851.043 | G7: 73.733002 | H7: 94.43733 | I7: =IFERROR(ROUND(H7,0),"null") -> 94 | J7: =IF(AND(A8=A7,I7=100,I8=100),"full access", " ") | K7: 4.9858808 | L7: 0.53183666 | M7: 0.044952533 | N7: 90.037538 | O7: =IFERROR(ROUND(N7,0),"null") -> 90 | P7: =IF(AND(A7=A8,O7=100,O8=100),"full access"," ") | Q7: =IFERROR(IF(A8=A7,((N7-N8)/(C7-C8)),""),"null") | R7: 8.7967221 | S7: 0.99460303 | T7: 0.17113693 | U7: 96.004736 | V7: =IFERROR(ROUND(U7,0),"null") -> 96 | W7: =IF(AND(A7=A8,V7=100,V8=100),"full access","") | X7: =IFERROR(IF(A8=A7,((U7-U8)/(C7-C8)),""),"null") | Y7: 3.6282886 | Z7: 0.36697555 | AA7: 0 | AB7: =IFERROR(IF(A8=A7, Q7-X7, ""), "null")
A8: American Samoa | B8: =VLOOKUP(A8,Regions!A:B,2,0) -> East Asia & Pacific | C8: 2015 | D8: =IF(A9=A8,ABS(C9-C8),"") -> 5 | E8: =IFERROR(IF(A9=A8,((H8-H9)/(C8-C9)), ""), "null") -> 0.030933702 | F8: 55.806 | G8: 87.238007 | H8: 99.619103 | I8: =IFERROR(ROUND(H8,0),"null") -> 100 | J8: =IF(AND(A9=A8,I8=100,I9=100),"full access", " ") -> full access | K8: 0 | L8: 0.38089685 | M8: 0 | N8: null | O8: =IFERROR(ROUND(N8,0),"null") -> null | P8: =IF(AND(A8=A9,O8=100,O9=100),"full access"," ") | Q8: =IFERROR(IF(A9=A8,((N8-N9)/(C8-C9)),""),"null") -> null | R8: null | S8: null | T8: null | U8: null | V8: =IFERROR(ROUND(U8,0),"null") -> null | W8: =IF(AND(A8=A9,V8=100,V9=100),"full access","") | X8: =IFERROR(IF(A9=A8,((U8-U9)/(C8-C9)),""),"null") -> null | Y8: null | Z8: null | AA8: null | AB8: =IFERROR(IF(A9=A8, Q8-X8, ""), "null") -> null
A9: American Samoa | B9: =VLOOKUP(A9,Regions!A:B,2,0) -> East Asia & Pacific | C9: 2020 | D9: =IF(A10=A9,ABS(C10-C9),"") | E9: =IFERROR(IF(A10=A9,((H9-H10)/(C9-C10)), ""), "null") | F9: 55.196999 | G9: 87.153 | H9: 99.773772 | I9: =IFERROR(ROUND(H9,0),"null") -> 100 | J9: =IF(AND(A10=A9,I9=100,I10=100),"full access", " ") | K9: 0 | L9: 0.22622834 | M9: 0 | N9: null | O9: =IFERROR(ROUND(N9,0),"null") -> null | P9: =IF(AND(A9=A10,O9=100,O10=100),"full access"," ") | Q9: =IFERROR(IF(A10=A9,((N9-N10)/(C9-C10)),""),"null") | R9: null | S9: null | T9: null | U9: null | V9: =IFERROR(ROUND(U9,0),"null") -> null | W9: =IF(AND(A9=A10,V9=100,V10=100),"full access","") | X9: =IFERROR(IF(A10=A9,((U9-U10)/(C9-C10)),""),"null") | Y9: null | Z9: null | AA9: null | AB9: =IFERROR(IF(A10=A9, Q9-X9, ""), "null")
A10: Andorra | B10: =VLOOKUP(A10,Regions!A:B,2,0) -> Europe & Central Asia | C10: 2015 | D10: =IF(A11=A10,ABS(C11-C10),"") -> 5 | E10: =IFERROR(IF(A11=A10,((H10-H11)/(C10-C11)), ""), "null") -> 1.23e-06 | F10: 77.992996 | G10: 88.344994 | H10: 99.999998 | I10: =IFERROR(ROUND(H10,0),"null") -> 100 | J10: =IF(AND(A11=A10,I10=100,I11=100),"full access", " ") -> full access | K10: 0 | L10: 2.4455384e-06 | M10: 0 | N10: 100 | O10: =IFERROR(ROUND(N10,0),"null") -> 100 | P10: =IF(AND(A10=A11,O10=100,O11=100),"full access"," ") -> full access | Q10: =IFERROR(IF(A11=A10,((N10-N11)/(C10-C11)),""),"null") -> 0 | R10: 0 | S10: 0 | T10: 0 | U10: 100 | V10: =IFERROR(ROUND(U10,0),"null") -> 100 | W10: =IF(AND(A10=A11,V10=100,V11=100),"full access","") -> full access | X10: =IFERROR(IF(A11=A10,((U10-U11)/(C10-C11)),""),"null") -> 0 | Y10: 0 | Z10: 0 | AA10: 0 | AB10: =IFERROR(IF(A11=A10, Q10-X10, ""), "null") -> 0
A11: Andorra | B11: =VLOOKUP(A11,Regions!A:B,2,0) -> Europe & Central Asia | C11: 2020 | D11: =IF(A12=A11,ABS(C12-C11),"") | E11: =IFERROR(IF(A12=A11,((H11-H12)/(C11-C12)), ""), "null") | F11: 77.264999 | G11: 87.916 | H11: 100 | I11: =IFERROR(ROUND(H11,0),"null") -> 100 | J11: =IF(AND(A12=A11,I11=100,I12=100),"full access", " ") | K11: 0 | L11: 0 | M11: 0 | N11: 100 | O11: =IFERROR(ROUND(N11,0),"null") -> 100 | P11: =IF(AND(A11=A12,O11=100,O12=100),"full access"," ") | Q11: =IFERROR(IF(A12=A11,((N11-N12)/(C11-C12)),""),"null") | R11: 0 | S11: 0 | T11: 0 | U11: 100 | V11: =IFERROR(ROUND(U11,0),"null") -> 100 | W11: =IF(AND(A11=A12,V11=100,V12=100),"full access","") | X11: =IFERROR(IF(A12=A11,((U11-U12)/(C11-C12)),""),"null") | Y11: 0 | Z11: 0 | AA11: 0 | AB11: =IFERROR(IF(A12=A11, Q11-X11, ""), "null")
A12: Angola | B12: =VLOOKUP(A12,Regions!A:B,2,0) -> Sub-Saharan Africa | C12: 2015 | D12: =IF(A13=A12,ABS(C13-C12),"") -> 5 | E12: =IFERROR(IF(A13=A12,((H12-H13)/(C12-C13)), ""), "null") -> 0.57016185 | F12: 27884.381 | G12: 63.445995 | H12: 54.316928 | I12: =IFERROR(ROUND(H12,0),"null") -> 54 | J12: =IF(AND(A13=A12,I12=100,I13=100),"full access", " ") | K12: 11.368619 | L12: 17.372356 | M12: 16.942097 | N12: 26.714369 | O12: =IFERROR(ROUND(N12,0),"null") -> 27 | P12: =IF(AND(A12=A13,O12=100,O13=100),"full access"," ") | Q12: =IFERROR(IF(A13=A12,((N12-N13)/(C12-C13)),""),"null") -> 0.21877144 | R12: 9.9310693 | S12: 21.725308 | T12: 41.629254 | U12: 70.219965 | V12: =IFERROR(ROUND(U12,0),"null") -> 70 | W12: =IF(AND(A12=A13,V12=100,V13=100),"full access","") | X12: =IFERROR(IF(A13=A12,((U12-U13)/(C12-C13)),""),"null") -> 0.3046367 | Y12: 12.196853 | Z12: 14.864431 | AA12: 2.7187499 | AB12: =IFERROR(IF(A13=A12, Q12-X12, ""), "null") -> -0.085865258
A13: Angola | B13: =VLOOKUP(A13,Regions!A:B,2,0) -> Sub-Saharan Africa | C13: 2020 | D13: =IF(A14=A13,ABS(C14-C13),"") | E13: =IFERROR(IF(A14=A13,((H13-H14)/(C13-C14)), ""), "null") | F13: 32866.27 | G13: 66.824997 | H13: 57.167738 | I13: =IFERROR(ROUND(H13,0),"null") -> 57 | J13: =IF(AND(A14=A13,I13=100,I14=100),"full access", " ") | K13: 9.2873499 | L13: 19.450825 | M13: 14.094087 | N13: 27.808227 | O13: =IFERROR(ROUND(N13,0),"null") -> 28 | P13: =IF(AND(A13=A14,O13=100,O14=100),"full access"," ") | Q13: =IFERROR(IF(A14=A13,((N13-N14)/(C13-C14)),""),"null") | R13: 8.7404884 | S13: 22.933153 | T13: 40.518132 | U13: 71.743149 | V13: =IFERROR(ROUND(U13,0),"null") -> 72 | W13: =IF(AND(A13=A14,V13=100,V14=100),"full access","") | X13: =IFERROR(IF(A14=A13,((U13-U14)/(C13-C14)),""),"null") | Y13: 9.5588375 | Z13: 17.722035 | AA13: 0.97597916 | AB13: =IFERROR(IF(A14=A13, Q13-X13, ""), "null")
A14: Anguilla | B14: =VLOOKUP(A14,Regions!A:B,2,0) -> Latin America & Caribbean | C14: 2015 | D14: =IF(A15=A14,ABS(C15-C14),"") -> 2 | E14: =IFERROR(IF(A15=A14,((H14-H15)/(C14-C15)), ""), "null") -> 0 | F14: 14.279 | G14: 100 | H14: 97.482274 | I14: =IFERROR(ROUND(H14,0),"null") -> 97 | J14: =IF(AND(A15=A14,I14=100,I15=100),"full access", " ") | K14: 0 | L14: 2.5177258 | M14: 0 | N14: null | O14: =IFERROR(ROUND(N14,0),"null") -> null | P14: =IF(AND(A14=A15,O14=100,O15=100),"full access"," ") | Q14: =IFERROR(IF(A15=A14,((N14-N15)/(C14-C15)),""),"null") -> null | R14: null | S14: null | T14: null | U14: 97.482274 | V14: =IFERROR(ROUND(U14,0),"null") -> 97 | W14: =IF(AND(A14=A15,V14=100,V15=100),"full access","") | X14: =IFERROR(IF(A15=A14,((U14-U15)/(C14-C15)),""),"null") -> 0 | Y14: 0 | Z14: 2.5177258 | AA14: 0 | AB14: =IFERROR(IF(A15=A14, Q14-X14, ""), "null") -> null
A15: Anguilla | B15: =VLOOKUP(A15,Regions!A:B,2,0) -> Latin America & Caribbean | C15: 2017 | D15: =IF(A16=A15,ABS(C16-C15),"") | E15: =IFERROR(IF(A16=A15,((H15-H16)/(C15-C16)), ""), "null") | F15: 14.588 | G15: 100 | H15: 97.482274 | I15: =IFERROR(ROUND(H15,0),"null") -> 97 | J15: =IF(AND(A16=A15,I15=100,I16=100),"full access", " ") | K15: 0 | L15: 2.5177258 | M15: 0 | N15: null | O15: =IFERROR(ROUND(N15,0),"null") -> null | P15: =IF(AND(A15=A16,O15=100,O16=100),"full access"," ") | Q15: =IFERROR(IF(A16=A15,((N15-N16)/(C15-C16)),""),"null") | R15: null | S15: null | T15: null | U15: 97.482274 | V15: =IFERROR(ROUND(U15,0),"null") -> 97 | W15: =IF(AND(A15=A16,V15=100,V16=100),"full access","") | X15: =IFERROR(IF(A16=A15,((U15-U16)/(C15-C16)),""),"null") | Y15: 0 | Z15: 2.5177258 | AA15: 0 | AB15: =IFERROR(IF(A16=A15, Q15-X15, ""), "null")
A16: Antigua and Barbuda | B16: =VLOOKUP(A16,Regions!A:B,2,0) -> Latin America & Caribbean | C16: 2015 | D16: =IF(A17=A16,ABS(C17-C16),"") -> 2 | E16: =IFERROR(IF(A17=A16,((H16-H17)/(C16-C17)), ""), "null") -> 0 | F16: 93.570999 | G16: 25 | H16: 96.739186 | I16: =IFERROR(ROUND(H16,0),"null") -> 97 | J16: =IF(AND(A17=A16,I16=100,I17=100),"full access", " ") | K16: 0 | L16: 3.1663476 | M16: 0.094466114 | N16: null | O16: =IFERROR(ROUND(N16,0),"null") -> null | P16: =IF(AND(A16=A17,O16=100,O17=100),"full access"," ") | Q16: =IFERROR(IF(A17=A16,((N16-N17)/(C16-C17)),""),"null") -> null | R16: null | S16: null | T16: null | U16: null | V16: =IFERROR(ROUND(U16,0),"null") -> null | W16: =IF(AND(A16=A17,V16=100,V17=100),"full access","") | X16: =IFERROR(IF(A17=A16,((U16-U17)/(C16-C17)),""),"null") -> null | Y16: null | Z16: null | AA16: null | AB16: =IFERROR(IF(A17=A16, Q16-X16, ""), "null") -> null
A17: Antigua and Barbuda | B17: =VLOOKUP(A17,Regions!A:B,2,0) -> Latin America & Caribbean | C17: 2017 | D17: =IF(A18=A17,ABS(C18-C17),"") | E17: =IFERROR(IF(A18=A17,((H17-H18)/(C17-C18)), ""), "null") | F17: 95.425003 | G17: 24.713001 | H17: 96.739186 | I17: =IFERROR(ROUND(H17,0),"null") -> 97 | J17: =IF(AND(A18=A17,I17=100,I18=100),"full access", " ") | K17: 0 | L17: 3.1663476 | M17: 0.094466114 | N17: null | O17: =IFERROR(ROUND(N17,0),"null") -> null | P17: =IF(AND(A17=A18,O17=100,O18=100),"full access"," ") | Q17: =IFERROR(IF(A18=A17,((N17-N18)/(C17-C18)),""),"null") | R17: null | S17: null | T17: null | U17: null | V17: =IFERROR(ROUND(U17,0),"null") -> null | W17: =IF(AND(A17=A18,V17=100,V18=100),"full access","") | X17: =IFERROR(IF(A18=A17,((U17-U18)/(C17-C18)),""),"null") | Y17: null | Z17: null | AA17: null | AB17: =IFERROR(IF(A18=A17, Q17-X17, ""), "null")
A18: Argentina | B18: =VLOOKUP(A18,Regions!A:B,2,0) -> Latin America & Caribbean | C18: 2015 | D18: =IF(A19=A18,ABS(C19-C18),"") -> 5 | E18: =IFERROR(IF(A19=A18,((H18-H19)/(C18-C19)), ""), "null") -> null | F18: 43075.414 | G18: 91.502998 | H18: 98.966588 | I18: =IFERROR(ROUND(H18,0),"null") -> 99 | J18: =IF(AND(A19=A18,I18=100,I19=100),"full access", " ") | K18: 0 | L18: 0.66491438 | M18: 0.36849747 | N18: 92.98366 | O18: =IFERROR(ROUND(N18,0),"null") -> 93 | P18: =IF(AND(A18=A19,O18=100,O19=100),"full access"," ") | Q18: =IFERROR(IF(A19=A18,((N18-N19)/(C18-C19)),""),"null") -> null | R18: 0 | S18: 2.6795449 | T18: 4.3367951 | U18: 99.522163 | V18: =IFERROR(ROUND(U18,0),"null") -> 100 | W18: =IF(AND(A18=A19,V18=100,V19=100),"full access","") -> full access | X18: =IFERROR(IF(A19=A18,((U18-U19)/(C18-C19)),""),"null") -> 0.05365152 | Y18: 0 | Z18: 0.47783695 | AA18: 0 | AB18: =IFERROR(IF(A19=A18, Q18-X18, ""), "null") -> null
A19: Argentina | B19: =VLOOKUP(A19,Regions!A:B,2,0) -> Latin America & Caribbean | C19: 2020 | D19: =IF(A20=A19,ABS(C20-C19),"") | E19: =IFERROR(IF(A20=A19,((H19-H20)/(C19-C20)), ""), "null") | F19: 45195.777 | G19: 92.111 | H19: null | I19: =IFERROR(ROUND(H19,0),"null") -> null | J19: =IF(AND(A20=A19,I19=100,I20=100),"full access", " ") | K19: null | L19: null | M19: null | N19: null | O19: =IFERROR(ROUND(N19,0),"null") -> null | P19: =IF(AND(A19=A20,O19=100,O20=100),"full access"," ") | Q19: =IFERROR(IF(A20=A19,((N19-N20)/(C19-C20)),""),"null") | R19: null | S19: null | T19: null | U19: 99.790421 | V19: =IFERROR(ROUND(U19,0),"null") -> 100 | W19: =IF(AND(A19=A20,V19=100,V20=100),"full access","") | X19: =IFERROR(IF(A20=A19,((U19-U20)/(C19-C20)),""),"null") | Y19: 0 | Z19: 0.20957935 | AA19: 0 | AB19: =IFERROR(IF(A20=A19, Q19-X19, ""), "null")
A20: Armenia | B20: =VLOOKUP(A20,Regions!A:B,2,0) -> Europe & Central Asia | C20: 2015 | D20: =IF(A21=A20,ABS(C21-C20),"") -> 5 | E20: =IFERROR(IF(A21=A20,((H20-H21)/(C20-C21)), ""), "null") -> 0.083722798 | F20: 2925.5591 | G20: 63.085003 | H20: 99.552567 | I20: =IFERROR(ROUND(H20,0),"null") -> 100 | J20: =IF(AND(A21=A20,I20=100,I21=100),"full access", " ") -> full access | K20: 0 | L20: 0.098505084 | M20: 0.34892822 | N20: 99.054779 | O20: =IFERROR(ROUND(N20,0),"null") -> 99 | P20: =IF(AND(A20=A21,O20=100,O21=100),"full access"," ") | Q20: =IFERROR(IF(A21=A20,((N20-N21)/(C20-C21)),""),"null") -> 0.18904415 | R20: 0 | S20: 0 | T20: 0.94522073 | U20: 99.843853 | V20: =IFERROR(ROUND(U20,0),"null") -> 100 | W20: =IF(AND(A20=A21,V20=100,V21=100),"full access","") -> full access | X20: =IFERROR(IF(A21=A20,((U20-U21)/(C20-C21)),""),"null") -> 0.022125564 | Y20: 0 | Z20: 0.1561466 | AA20: 0 | AB20: =IFERROR(IF(A21=A20, Q20-X20, ""), "null") -> 0.16691858
A21: Armenia | B21: =VLOOKUP(A21,Regions!A:B,2,0) -> Europe & Central Asia | C21: 2020 | D21: =IF(A22=A21,ABS(C22-C21),"") | E21: =IFERROR(IF(A22=A21,((H21-H22)/(C21-C22)), ""), "null") | F21: 2963.2339 | G21: 63.313 | H21: 99.971181 | I21: =IFERROR(ROUND(H21,0),"null") -> 100 | J21: =IF(AND(A22=A21,I21=100,I22=100),"full access", " ") | K21: 0 | L21: 0.028819308 | M21: 0 | N21: 100 | O21: =IFERROR(ROUND(N21,0),"null") -> 100 | P21: =IF(AND(A21=A22,O21=100,O22=100),"full access"," ") | Q21: =IFERROR(IF(A22=A21,((N21-N22)/(C21-C22)),""),"null") | R21: 0 | S21: 0 | T21: 0 | U21: 99.954481 | V21: =IFERROR(ROUND(U21,0),"null") -> 100 | W21: =IF(AND(A21=A22,V21=100,V22=100),"full access","") | X21: =IFERROR(IF(A22=A21,((U21-U22)/(C21-C22)),""),"null") | Y21: 0 | Z21: 0.045518784 | AA21: 0 | AB21: =IFERROR(IF(A22=A21, Q21-X21, ""), "null")
A22: Aruba | B22: =VLOOKUP(A22,Regions!A:B,2,0) -> Latin America & Caribbean | C22: 2015 | D22: =IF(A23=A22,ABS(C23-C22),"") -> 1 | E22: =IFERROR(IF(A23=A22,((H22-H23)/(C22-C23)), ""), "null") -> 0 | F22: 104.339 | G22: 43.108002 | H22: 97.869023 | I22: =IFERROR(ROUND(H22,0),"null") -> 98 | J22: =IF(AND(A23=A22,I22=100,I23=100),"full access", " ") | K22: 0 | L22: 1.9599362 | M22: 0.17104041 | N22: null | O22: =IFERROR(ROUND(N22,0),"null") -> null | P22: =IF(AND(A22=A23,O22=100,O23=100),"full access"," ") | Q22: =IFERROR(IF(A23=A22,((N22-N23)/(C22-C23)),""),"null") -> null | R22: null | S22: null | T22: null | U22: null | V22: =IFERROR(ROUND(U22,0),"null") -> null | W22: =IF(AND(A22=A23,V22=100,V23=100),"full access","") | X22: =IFERROR(IF(A23=A22,((U22-U23)/(C22-C23)),""),"null") -> null | Y22: null | Z22: null | AA22: null | AB22: =IFERROR(IF(A23=A22, Q22-X22, ""), "null") -> null
A23: Aruba | B23: =VLOOKUP(A23,Regions!A:B,2,0) -> Latin America & Caribbean | C23: 2016 | D23: =IF(A24=A23,ABS(C24-C23),"") | E23: =IFERROR(IF(A24=A23,((H23-H24)/(C23-C24)), ""), "null") | F23: 104.865 | G23: 43.191998 | H23: 97.869023 | I23: =IFERROR(ROUND(H23,0),"null") -> 98 | J23: =IF(AND(A24=A23,I23=100,I24=100),"full access", " ") | K23: 0 | L23: 1.9599362 | M23: 0.17104041 | N23: null | O23: =IFERROR(ROUND(N23,0),"null") -> null | P23: =IF(AND(A23=A24,O23=100,O24=100),"full access"," ") | Q23: =IFERROR(IF(A24=A23,((N23-N24)/(C23-C24)),""),"null") | R23: null | S23: null | T23: null | U23: null | V23: =IFERROR(ROUND(U23,0),"null") -> null | W23: =IF(AND(A23=A24,V23=100,V24=100),"full access","") | X23: =IFERROR(IF(A24=A23,((U23-U24)/(C23-C24)),""),"null") | Y23: null | Z23: null | AA23: null | AB23: =IFERROR(IF(A24=A23, Q23-X23, ""), "null")
A24: Australia | B24: =VLOOKUP(A24,Regions!A:B,2,0) -> East Asia & Pacific | C24: 2015 | D24: =IF(A25=A24,ABS(C25-C24),"") -> 5 | E24: =IFERROR(IF(A25=A24,((H24-H25)/(C24-C25)), ""), "null") -> -3.877e-05 | F24: 23932.498 | G24: 85.701004 | H24: 99.970006 | I24: =IFERROR(ROUND(H24,0),"null") -> 100 | J24: =IF(AND(A25=A24,I24=100,I25=100),"full access", " ") -> full access | K24: 0 | L24: 0.029994331 | M24: 0 | N24: 100 | O24: =IFERROR(ROUND(N24,0),"null") -> 100 | P24: =IF(AND(A24=A25,O24=100,O25=100),"full access"," ") -> full access | Q24: =IFERROR(IF(A25=A24,((N24-N25)/(C24-C25)),""),"null") -> 0 | R24: 0 | S24: 0 | T24: 0 | U24: 99.965 | V24: =IFERROR(ROUND(U24,0),"null") -> 100 | W24: =IF(AND(A24=A25,V24=100,V25=100),"full access","") -> full access | X24: =IFERROR(IF(A25=A24,((U24-U25)/(C24-C25)),""),"null") -> 0 | Y24: 0 | Z24: 0.035 | AA24: 0 | AB24: =IFERROR(IF(A25=A24, Q24-X24, ""), "null") -> 0
A25: Australia | B25: =VLOOKUP(A25,Regions!A:B,2,0) -> East Asia & Pacific | C25: 2020 | D25: =IF(A26=A25,ABS(C26-C25),"") | E25: =IFERROR(IF(A26=A25,((H25-H26)/(C25-C26)), ""), "null") | F25: 25499.881 | G25: 86.240997 | H25: 99.969812 | I25: =IFERROR(ROUND(H25,0),"null") -> 100 | J25: =IF(AND(A26=A25,I25=100,I26=100),"full access", " ") | K25: 0 | L25: 0.030188179 | M25: 0 | N25: 100 | O25: =IFERROR(ROUND(N25,0),"null") -> 100 | P25: =IF(AND(A25=A26,O25=100,O26=100),"full access"," ") | Q25: =IFERROR(IF(A26=A25,((N25-N26)/(C25-C26)),""),"null") | R25: 0 | S25: 0 | T25: 0 | U25: 99.965 | V25: =IFERROR(ROUND(U25,0),"null") -> 100 | W25: =IF(AND(A25=A26,V25=100,V26=100),"full access","") | X25: =IFERROR(IF(A26=A25,((U25-U26)/(C25-C26)),""),"null") | Y25: 0 | Z25: 0.035 | AA25: 0 | AB25: =IFERROR(IF(A26=A25, Q25-X25, ""), "null")
A26: Austria | B26: =VLOOKUP(A26,Regions!A:B,2,0) -> Europe & Central Asia | C26: 2015 | D26: =IF(A27=A26,ABS(C27-C26),"") -> 5 | E26: =IFERROR(IF(A27=A26,((H26-H27)/(C26-C27)), ""), "null") -> 0 | F26: 8678.667 | G26: 57.715 | H26: 100 | I26: =IFERROR(ROUND(H26,0),"null") -> 100 | J26: =IF(AND(A27=A26,I26=100,I27=100),"full access", " ") -> full access | K26: 0 | L26: 0 | M26: 0 | N26: 100 | O26: =IFERROR(ROUND(N26,0),"null") -> 100 | P26: =IF(AND(A26=A27,O26=100,O27=100),"full access"," ") -> full access | Q26: =IFERROR(IF(A27=A26,((N26-N27)/(C26-C27)),""),"null") -> 0 | R26: 0 | S26: 0 | T26: 0 | U26: 100 | V26: =IFERROR(ROUND(U26,0),"null") -> 100 | W26: =IF(AND(A26=A27,V26=100,V27=100),"full access","") -> full access | X26: =IFERROR(IF(A27=A26,((U26-U27)/(C26-C27)),""),"null") -> 0 | Y26: 0 | Z26: 0 | AA26: 0 | AB26: =IFERROR(IF(A27=A26, Q26-X26, ""), "null") -> 0
A27: Austria | B27: =VLOOKUP(A27,Regions!A:B,2,0) -> Europe & Central Asia | C27: 2020 | D27: =IF(A28=A27,ABS(C28-C27),"") | E27: =IFERROR(IF(A28=A27,((H27-H28)/(C27-C28)), ""), "null") | F27: 9006.4004 | G27: 58.748001 | H27: 100 | I27: =IFERROR(ROUND(H27,0),"null") -> 100 | J27: =IF(AND(A28=A27,I27=100,I28=100),"full access", " ") | K27: 0 | L27: 0 | M27: 0 | N27: 100 | O27: =IFERROR(ROUND(N27,0),"null") -> 100 | P27: =IF(AND(A27=A28,O27=100,O28=100),"full access"," ") | Q27: =IFERROR(IF(A28=A27,((N27-N28)/(C27-C28)),""),"null") | R27: 0 | S27: 0 | T27: 0 | U27: 100 | V27: =IFERROR(ROUND(U27,0),"null") -> 100 | W27: =IF(AND(A27=A28,V27=100,V28=100),"full access","") | X27: =IFERROR(IF(A28=A27,((U27-U28)/(C27-C28)),""),"null") | Y27: 0 | Z27: 0 | AA27: 0 | AB27: =IFERROR(IF(A28=A27, Q27-X27, ""), "null")
A28: Azerbaijan | B28: =VLOOKUP(A28,Regions!A:B,2,0) -> Europe & Central Asia | C28: 2015 | D28: =IF(A29=A28,ABS(C29-C28),"") -> 5 | E28: =IFERROR(IF(A29=A28,((H28-H29)/(C28-C29)), ""), "null") -> 0.72461243 | F28: 9622.7412 | G28: 54.714001 | H28: 92.420314 | I28: =IFERROR(ROUND(H28,0),"null") -> 92 | J28: =IF(AND(A29=A28,I28=100,I29=100),"full access", " ") | K28: 1.0022424 | L28: 4.3650895 | M28: 2.2123541 | N28: 84.143213 | O28: =IFERROR(ROUND(N28,0),"null") -> 84 | P28: =IF(AND(A28=A29,O28=100,O29=100),"full access"," ") | Q28: =IFERROR(IF(A29=A28,((N28-N29)/(C28-C29)),""),"null") -> 1.3565169 | R28: 2.2131397 | S28: 8.988206 | T28: 4.655441 | U28: 99.271152 | V28: =IFERROR(ROUND(U28,0),"null") -> 99 | W28: =IF(AND(A28=A29,V28=100,V29=100),"full access","") | X28: =IFERROR(IF(A29=A28,((U28-U29)/(C28-C29)),""),"null") -> 0.14576959 | Y28: 0 | Z28: 0.53860203 | AA28: 0.19024593 | AB28: =IFERROR(IF(A29=A28, Q28-X28, ""), "null") -> 1.2107473
A29: Azerbaijan | B29: =VLOOKUP(A29,Regions!A:B,2,0) -> Europe & Central Asia | C29: 2020 | D29: =IF(A30=A29,ABS(C30-C29),"") | E29: =IFERROR(IF(A30=A29,((H29-H30)/(C29-C30)), ""), "null") | F29: 10139.175 | G29: 56.397003 | H29: 96.043376 | I29: =IFERROR(ROUND(H29,0),"null") -> 96 | J29: =IF(AND(A30=A29,I29=100,I30=100),"full access", " ") | K29: 1.0427812 | L29: 2.9138427 | M29: 0 | N29: 90.925798 | O29: =IFERROR(ROUND(N29,0),"null") -> 91 | P29: =IF(AND(A29=A30,O29=100,O30=100),"full access"," ") | Q29: =IFERROR(IF(A30=A29,((N29-N30)/(C29-C30)),""),"null") | R29: 2.3915357 | S29: 6.6826664 | T29: 0 | U29: 100 | V29: =IFERROR(ROUND(U29,0),"null") -> 100 | W29: =IF(AND(A29=A30,V29=100,V30=100),"full access","") | X29: =IFERROR(IF(A30=A29,((U29-U30)/(C29-C30)),""),"null") | Y29: 0 | Z29: 0 | AA29: 0 | AB29: =IFERROR(IF(A30=A29, Q29-X29, ""), "null")
A30: Bahamas | B30: =VLOOKUP(A30,Regions!A:B,2,0) -> Latin America & Caribbean | C30: 2015 | D30: =IF(A31=A30,ABS(C31-C30),"") -> 4 | E30: =IFERROR(IF(A31=A30,((H30-H31)/(C30-C31)), ""), "null") -> 0 | F30: 374.20001 | G30: 82.745995 | H30: 98.886961 | I30: =IFERROR(ROUND(H30,0),"null") -> 99 | J30: =IF(AND(A31=A30,I30=100,I31=100),"full access", " ") | K30: 0 | L30: 1.1130395 | M30: 0 | N30: null | O30: =IFERROR(ROUND(N30,0),"null") -> null | P30: =IF(AND(A30=A31,O30=100,O31=100),"full access"," ") | Q30: =IFERROR(IF(A31=A30,((N30-N31)/(C30-C31)),""),"null") -> null | R30: null | S30: null | T30: null | U30: null | V30: =IFERROR(ROUND(U30,0),"null") -> null | W30: =IF(AND(A30=A31,V30=100,V31=100),"full access","") | X30: =IFERROR(IF(A31=A30,((U30-U31)/(C30-C31)),""),"null") -> null | Y30: null | Z30: null | AA30: null | AB30: =IFERROR(IF(A31=A30, Q30-X30, ""), "null") -> null
A31: Bahamas | B31: =VLOOKUP(A31,Regions!A:B,2,0) -> Latin America & Caribbean | C31: 2019 | D31: =IF(A32=A31,ABS(C32-C31),"") | E31: =IFERROR(IF(A32=A31,((H31-H32)/(C31-C32)), ""), "null") | F31: 389.48599 | G31: 83.131996 | H31: 98.886961 | I31: =IFERROR(ROUND(H31,0),"null") -> 99 | J31: =IF(AND(A32=A31,I31=100,I32=100),"full access", " ") | K31: 0 | L31: 1.1130395 | M31: 0 | N31: null | O31: =IFERROR(ROUND(N31,0),"null") -> null | P31: =IF(AND(A31=A32,O31=100,O32=100),"full access"," ") | Q31: =IFERROR(IF(A32=A31,((N31-N32)/(C31-C32)),""),"null") | R31: null | S31: null | T31: null | U31: null | V31: =IFERROR(ROUND(U31,0),"null") -> null | W31: =IF(AND(A31=A32,V31=100,V32=100),"full access","") | X31: =IFERROR(IF(A32=A31,((U31-U32)/(C31-C32)),""),"null") | Y31: null | Z31: null | AA31: null | AB31: =IFERROR(IF(A32=A31, Q31-X31, ""), "null")
A32: Bahrain | B32: =VLOOKUP(A32,Regions!A:B,2,0) -> Europe & Central Asia | C32: 2015 | D32: =IF(A33=A32,ABS(C33-C32),"") -> 5 | E32: =IFERROR(IF(A33=A32,((H32-H33)/(C32-C33)), ""), "null") -> 0 | F32: 1371.853 | G32: 88.998993 | H32: 100 | I32: =IFERROR(ROUND(H32,0),"null") -> 100 | J32: =IF(AND(A33=A32,I32=100,I33=100),"full access", " ") -> full access | K32: 0 | L32: 0 | M32: 0 | N32: null | O32: =IFERROR(ROUND(N32,0),"null") -> null | P32: =IF(AND(A32=A33,O32=100,O33=100),"full access"," ") | Q32: =IFERROR(IF(A33=A32,((N32-N33)/(C32-C33)),""),"null") -> null | R32: null | S32: null | T32: null | U32: null | V32: =IFERROR(ROUND(U32,0),"null") -> null | W32: =IF(AND(A32=A33,V32=100,V33=100),"full access","") | X32: =IFERROR(IF(A33=A32,((U32-U33)/(C32-C33)),""),"null") -> null | Y32: null | Z32: null | AA32: null | AB32: =IFERROR(IF(A33=A32, Q32-X32, ""), "null") -> null
A33: Bahrain | B33: =VLOOKUP(A33,Regions!A:B,2,0) -> Europe & Central Asia | C33: 2020 | D33: =IF(A34=A33,ABS(C34-C33),"") | E33: =IFERROR(IF(A34=A33,((H33-H34)/(C33-C34)), ""), "null") | F33: 1701.583 | G33: 89.506004 | H33: 100 | I33: =IFERROR(ROUND(H33,0),"null") -> 100 | J33: =IF(AND(A34=A33,I33=100,I34=100),"full access", " ") | K33: 0 | L33: 0 | M33: 0 | N33: null | O33: =IFERROR(ROUND(N33,0),"null") -> null | P33: =IF(AND(A33=A34,O33=100,O34=100),"full access"," ") | Q33: =IFERROR(IF(A34=A33,((N33-N34)/(C33-C34)),""),"null") | R33: null | S33: null | T33: null | U33: null | V33: =IFERROR(ROUND(U33,0),"null") -> null | W33: =IF(AND(A33=A34,V33=100,V34=100),"full access","") | X33: =IFERROR(IF(A34=A33,((U33-U34)/(C33-C34)),""),"null") | Y33: null | Z33: null | AA33: null | AB33: =IFERROR(IF(A34=A33, Q33-X33, ""), "null")
A34: Bangladesh | B34: =VLOOKUP(A34,Regions!A:B,2,0) -> South Asia | C34: 2015 | D34: =IF(A35=A34,ABS(C35-C34),"") -> 5 | E34: =IFERROR(IF(A35=A34,((H34-H35)/(C34-C35)), ""), "null") -> 0.11927156 | F34: 156256.28 | G34: 34.308002 | H34: 97.101602 | I34: =IFERROR(ROUND(H34,0),"null") -> 97 | J34: =IF(AND(A35=A34,I34=100,I35=100),"full access", " ") | K34: 1.087989 | L34: 0.72156166 | M34: 1.0888469 | N34: 96.773011 | O34: =IFERROR(ROUND(N34,0),"null") -> 97 | P34: =IF(AND(A34=A35,O34=100,O35=100),"full access"," ") | Q34: =IFERROR(IF(A35=A34,((N34-N35)/(C34-C35)),""),"null") -> 0.2214453 | R34: 1.0462142 | S34: 0.73174732 | T34: 1.4490272 | U34: 97.73078 | V34: =IFERROR(ROUND(U34,0),"null") -> 98 | W34: =IF(AND(A34=A35,V34=100,V35=100),"full access","") | X34: =IFERROR(IF(A35=A34,((U34-U35)/(C34-C35)),""),"null") -> -0.065600342 | Y34: 1.1679782 | Z34: 0.70205843 | AA34: 0.39918371 | AB34: =IFERROR(IF(A35=A34, Q34-X34, ""), "null") -> 0.28704564
A35: Bangladesh | B35: =VLOOKUP(A35,Regions!A:B,2,0) -> South Asia | C35: 2020 | D35: =IF(A36=A35,ABS(C36-C35),"") | E35: =IFERROR(IF(A36=A35,((H35-H36)/(C35-C36)), ""), "null") | F35: 164689.39 | G35: 38.177002 | H35: 97.69796 | I35: =IFERROR(ROUND(H35,0),"null") -> 98 | J35: =IF(AND(A36=A35,I35=100,I36=100),"full access", " ") | K35: 1.1564259 | L35: 0.4626557 | M35: 0.68295817 | N35: 97.880238 | O35: =IFERROR(ROUND(N35,0),"null") -> 98 | P35: =IF(AND(A35=A36,O35=100,O36=100),"full access"," ") | Q35: =IFERROR(IF(A36=A35,((N35-N36)/(C35-C36)),""),"null") | R35: 0.85810498 | S35: 0.31648024 | T35: 0.94517702 | U35: 97.402778 | V35: =IFERROR(ROUND(U35,0),"null") -> 97 | W35: =IF(AND(A35=A36,V35=100,V36=100),"full access","") | X35: =IFERROR(IF(A36=A35,((U35-U36)/(C35-C36)),""),"null") | Y35: 1.6395201 | Z35: 0.69937521 | AA35: 0.25832669 | AB35: =IFERROR(IF(A36=A35, Q35-X35, ""), "null")
A36: Barbados | B36: =VLOOKUP(A36,Regions!A:B,2,0) -> Latin America & Caribbean | C36: 2015 | D36: =IF(A37=A36,ABS(C37-C36),"") -> 5 | E36: =IFERROR(IF(A37=A36,((H36-H37)/(C36-C37)), ""), "null") -> 0.008001136 | F36: 285.327 | G36: 31.248999 | H36: 98.474445 | I36: =IFERROR(ROUND(H36,0),"null") -> 98 | J36: =IF(AND(A37=A36,I36=100,I37=100),"full access", " ") | K36: 0.26749191 | L36: 1.2580634 | M36: 0 | N36: null | O36: =IFERROR(ROUND(N36,0),"null") -> null | P36: =IF(AND(A36=A37,O36=100,O37=100),"full access"," ") | Q36: =IFERROR(IF(A37=A36,((N36-N37)/(C36-C37)),""),"null") -> null | R36: null | S36: null | T36: null | U36: null | V36: =IFERROR(ROUND(U36,0),"null") -> null | W36: =IF(AND(A36=A37,V36=100,V37=100),"full access","") | X36: =IFERROR(IF(A37=A36,((U36-U37)/(C36-C37)),""),"null") -> null | Y36: null | Z36: null | AA36: null | AB36: =IFERROR(IF(A37=A36, Q36-X36, ""), "null") -> null
A37: Barbados | B37: =VLOOKUP(A37,Regions!A:B,2,0) -> Latin America & Caribbean | C37: 2020 | D37: =IF(A38=A37,ABS(C38-C37),"") | E37: =IFERROR(IF(A38=A37,((H37-H38)/(C37-C38)), ""), "null") | F37: 287.371 | G37: 31.191 | H37: 98.51445 | I37: =IFERROR(ROUND(H37,0),"null") -> 99 | J37: =IF(AND(A38=A37,I37=100,I38=100),"full access", " ") | K37: 0.26760058 | L37: 1.217949 | M37: 0 | N37: null | O37: =IFERROR(ROUND(N37,0),"null") -> null | P37: =IF(AND(A37=A38,O37=100,O38=100),"full access"," ") | Q37: =IFERROR(IF(A38=A37,((N37-N38)/(C37-C38)),""),"null") | R37: null | S37: null | T37: null | U37: null | V37: =IFERROR(ROUND(U37,0),"null") -> null | W37: =IF(AND(A37=A38,V37=100,V38=100),"full access","") | X37: =IFERROR(IF(A38=A37,((U37-U38)/(C37-C38)),""),"null") | Y37: null | Z37: null | AA37: null | AB37: =IFERROR(IF(A38=A37, Q37-X37, ""), "null")
A38: Belarus | B38: =VLOOKUP(A38,Regions!A:B,2,0) -> Europe & Central Asia | C38: 2015 | D38: =IF(A39=A38,ABS(C39-C38),"") -> 5 | E38: =IFERROR(IF(A39=A38,((H38-H39)/(C38-C39)), ""), "null") -> 0.011531798 | F38: 9439.4238 | G38: 77.181 | H38: 96.477067 | I38: =IFERROR(ROUND(H38,0),"null") -> 96 | J38: =IF(AND(A39=A38,I38=100,I39=100),"full access", " ") | K38: 3.3001301 | L38: 0.2228028 | M38: 0 | N38: 98.330672 | O38: =IFERROR(ROUND(N38,0),"null") -> 98 | P38: =IF(AND(A38=A39,O38=100,O39=100),"full access"," ") | Q38: =IFERROR(IF(A39=A38,((N38-N39)/(C38-C39)),""),"null") -> 0.046690142 | R38: 0.99323911 | S38: 0.67608929 | T38: 0 | U38: 95.929035 | V38: =IFERROR(ROUND(U38,0),"null") -> 96 | W38: =IF(AND(A38=A39,V38=100,V39=100),"full access","") | X38: =IFERROR(IF(A39=A38,((U38-U39)/(C38-C39)),""),"null") -> 0.016367688 | Y38: 3.9821754 | Z38: 0.088789424 | AA38: 0 | AB38: =IFERROR(IF(A39=A38, Q38-X38, ""), "null") -> 0.030322454
A39: Belarus | B39: =VLOOKUP(A39,Regions!A:B,2,0) -> Europe & Central Asia | C39: 2020 | D39: =IF(A40=A39,ABS(C40-C39),"") | E39: =IFERROR(IF(A40=A39,((H39-H40)/(C39-C40)), ""), "null") | F39: 9449.3213 | G39: 79.483002 | H39: 96.534726 | I39: =IFERROR(ROUND(H39,0),"null") -> 97 | J39: =IF(AND(A40=A39,I39=100,I40=100),"full access", " ") | K39: 3.3721195 | L39: 0.093154368 | M39: 0 | N39: 98.564122 | O39: =IFERROR(ROUND(N39,0),"null") -> 99 | P39: =IF(AND(A39=A40,O39=100,O40=100),"full access"," ") | Q39: =IFERROR(IF(A40=A39,((N39-N40)/(C39-C40)),""),"null") | R39: 0.9955972 | S39: 0.44028049 | T39: 0 | U39: 96.010874 | V39: =IFERROR(ROUND(U39,0),"null") -> 96 | W39: =IF(AND(A39=A40,V39=100,V40=100),"full access","") | X39: =IFERROR(IF(A40=A39,((U39-U40)/(C39-C40)),""),"null") | Y39: 3.9855726 | Z39: 0.003553732 | AA39: 0 | AB39: =IFERROR(IF(A40=A39, Q39-X39, ""), "null")
A40: Belgium | B40: =VLOOKUP(A40,Regions!A:B,2,0) -> Europe & Central Asia | C40: 2015 | D40: =IF(A41=A40,ABS(C41-C40),"") -> 5 | E40: =IFERROR(IF(A41=A40,((H40-H41)/(C40-C41)), ""), "null") -> -2.5e-07 | F40: 11287.931 | G40: 97.875999 | H40: 99.999998 | I40: =IFERROR(ROUND(H40,0),"null") -> 100 | J40: =IF(AND(A41=A40,I40=100,I41=100),"full access", " ") -> full access | K40: 0 | L40: 2.2980245e-06 | M40: 0 | N40: 100 | O40: =IFERROR(ROUND(N40,0),"null") -> 100 | P40: =IF(AND(A40=A41,O40=100,O41=100),"full access"," ") -> full access | Q40: =IFERROR(IF(A41=A40,((N40-N41)/(C40-C41)),""),"null") -> 0 | R40: 0 | S40: 0 | T40: 0 | U40: 100 | V40: =IFERROR(ROUND(U40,0),"null") -> 100 | W40: =IF(AND(A40=A41,V40=100,V41=100),"full access","") -> full access | X40: =IFERROR(IF(A41=A40,((U40-U41)/(C40-C41)),""),"null") -> 0 | Y40: 0 | Z40: 0 | AA40: 0 | AB40: =IFERROR(IF(A41=A40, Q40-X40, ""), "null") -> 0
...

Sheet Summary Sheet
A1: 1a | B1: During which years was water access data recorded? | I1: 2a | J1: What is the minimum, maximum and average annual rate of change in water access for national, urban and rural populations? | T1: 3a | U1: How does the rate of change in water access vary across regions and population sizes?
B3: Year | C3: Count of records | J3: Feature | K3: Min | L3: Average | M3: Max | N3: Full Access | O3: ARC = 0 (-full access) | P3: ARC < 0 | Q3: ARC > 0 | R3: No Value | U3: Region | V3: No. of Countries | W3: Avg ARC_n | X3: Avg ARC_u | Y3: Avg ARC_r
B4: 2015 | C4: =COUNTIF('Estimates of the use of water ('!$C$2:$C$463,$B4) -> 231 | J4: Arc_n | K4: =MIN('Estimates of the use of water ('!E:E) -> -1.0217887 | L4: =AVERAGE('Estimates of the use of water ('!E:E) -> 0.27703545 | M4: =MAX('Estimates of the use of water ('!E:E) -> 2.7503265 | N4: =COUNTIF('Estimates of the use of water ('!J:J,"full access") -> 62 | O4: =COUNTIFS('Estimates of the use of water ('!E:E,0,'Estimates of the use of water ('!J:J,"<>full access") -> 16 | P4: =COUNTIFS('Estimates of the use of water ('!E:E,"<0",'Estimates of the use of water ('!J:J,"<>full access") -> 16 | Q4: =COUNTIFS('Estimates of the use of water ('!E:E,">0",'Estimates of the use of water ('!J:J,"<>full access") -> 135 | R4: =COUNTIF('Estimates of the use of water ('!E:E,"null") -> 2 | U4: Sub-Saharan Africa | V4: =COUNTIFS('Estimates of the use of water ('!B:B,"Sub-Saharan Africa",'Estimates of the use of water ('!D:D,"<>")/2 -> 53 | W4: =AVERAGEIF('Estimates of the use of water ('!B:B,"Sub-Saharan Africa",'Estimates of the use of water ('!E:E) -> 0.55953947 | X4: =AVERAGEIF('Estimates of the use of water ('!B:B,"Sub-Saharan Africa",'Estimates of the use of water ('!X:X) -> 0.27079472 | Y4: =AVERAGEIF('Estimates of the use of water ('!B:B,"Sub-Saharan Africa",'Estimates of the use of water ('!Q:Q) -> 0.60306315
B5: 2016 | C5: =COUNTIF('Estimates of the use of water ('!$C$2:$C$463,$B5) -> 3 | J5: Arc_u | K5: =MIN('Estimates of the use of water ('!X:X) -> -1.6200868 | L5: =AVERAGE('Estimates of the use of water ('!X:X) -> 0.15493928 | M5: =MAX('Estimates of the use of water ('!X:X) -> 2.6682119 | N5: =COUNTIF('Estimates of the use of water ('!W:W,"full access") -> 55 | O5: =COUNTIFS('Estimates of the use of water ('!X:X,0,'Estimates of the use of water ('!W:W,"<>full access") -> 7 | P5: =COUNTIFS('Estimates of the use of water ('!X:X,"<0",'Estimates of the use of water ('!W:W,"<>full access") -> 26 | Q5: =COUNTIFS('Estimates of the use of water ('!X:X,">0",'Estimates of the use of water ('!W:W,"<>full access") -> 93 | R5: =COUNTIF('Estimates of the use of water ('!X:X,"null") -> 50 | U5: South Asia | V5: =COUNTIFS('Estimates of the use of water ('!B:B,"South Asia",'Estimates of the use of water ('!D:D,"<>")/2 -> 11 | W5: =AVERAGEIF('Estimates of the use of water ('!B:B,"South Asia",'Estimates of the use of water ('!E:E) -> 0.4802304 | X5: =AVERAGEIF('Estimates of the use of water ('!B:B,"South Asia",'Estimates of the use of water ('!X:X) -> 0.26548867 | Y5: =AVERAGEIF('Estimates of the use of water ('!B:B,"South Asia",'Estimates of the use of water ('!Q:Q) -> 0.55914463
B6: 2017 | C6: =COUNTIF('Estimates of the use of water ('!$C$2:$C$463,$B6) -> 9 | J6: Arc_r | K6: =MIN('Estimates of the use of water ('!Q:Q) -> -1.227381 | L6: =AVERAGE('Estimates of the use of water ('!Q:Q) -> 0.48415546 | M6: =MAX('Estimates of the use of water ('!Q:Q) -> 2.6678826 | N6: =COUNTIF('Estimates of the use of water ('!P:P,"full access") -> 29 | O6: =COUNTIFS('Estimates of the use of water ('!Q:Q,0,'Estimates of the use of water ('!P:P,"<>full access") -> 5 | P6: =COUNTIFS('Estimates of the use of water ('!Q:Q,"<0",'Estimates of the use of water ('!P:P,"<>full access") -> 17 | Q6: =COUNTIFS('Estimates of the use of water ('!Q:Q,">0",'Estimates of the use of water ('!P:P,"<>full access") -> 116 | R6: =COUNTIF('Estimates of the use of water ('!Q:Q,"null") -> 64 | U6: East Asia & Pacific | V6: =COUNTIFS('Estimates of the use of water ('!B:B,"East Asia & Pacific",'Estimates of the use of water ('!D:D,"<>")/2 -> 40 | W6: =AVERAGEIF('Estimates of the use of water ('!B:B,"East Asia & Pacific",'Estimates of the use of water ('!E:E) -> 0.2784349 | X6: =AVERAGEIF('Estimates of the use of water ('!B:B,"East Asia & Pacific",'Estimates of the use of water ('!X:X) -> 0.23295792 | Y6: =AVERAGEIF('Estimates of the use of water ('!B:B,"East Asia & Pacific",'Estimates of the use of water ('!Q:Q) -> 0.5077948
B7: 2018 | C7: =COUNTIF('Estimates of the use of water ('!$C$2:$C$463,$B7) -> 2 | U7: Europe & Central Asia | V7: =COUNTIFS('Estimates of the use of water ('!B:B,"Europe & Central Asia",'Estimates of the use of water ('!D:D,"<>")/2 -> 64 | W7: =AVERAGEIF('Estimates of the use of water ('!B:B,"Europe & Central Asia",'Estimates of the use of water ('!E:E) -> 0.11168578 | X7: =AVERAGEIF('Estimates of the use of water ('!B:B,"Europe & Central Asia",'Estimates of the use of water ('!X:X) -> 0.046995216 | Y7: =AVERAGEIF('Estimates of the use of water ('!B:B,"Europe & Central Asia",'Estimates of the use of water ('!Q:Q) -> 0.22440971
B8: 2019 | C8: =COUNTIF('Estimates of the use of water ('!$C$2:$C$463,$B8) -> 4 | U8: Latin America & Caribbean | V8: =COUNTIFS('Estimates of the use of water ('!B:B,"Latin America & Caribbean",'Estimates of the use of water ('!D:D,"<>")/2 -> 48 | W8: =AVERAGEIF('Estimates of the use of water ('!B:B,"Latin America & Caribbean",'Estimates of the use of water ('!E:E) -> 0.14442485 | X8: =AVERAGEIF('Estimates of the use of water ('!B:B,"Latin America & Caribbean",'Estimates of the use of water ('!X:X) -> 0.071521594 | Y8: =AVERAGEIF('Estimates of the use of water ('!B:B,"Latin America & Caribbean",'Estimates of the use of water ('!Q:Q) -> 0.6803145
B9: 2020 | C9: =COUNTIF('Estimates of the use of water ('!$C$2:$C$463,$B9) -> 213 | U9: Middle East & North Africa | V9: =COUNTIFS('Estimates of the use of water ('!B:B,"Middle East & North Africa",'Estimates of the use of water ('!D:D,"<>")/2 -> 10 | W9: =AVERAGEIF('Estimates of the use of water ('!B:B,"Middle East & North Africa",'Estimates of the use of water ('!E:E) -> 0.34556302 | X9: =AVERAGEIF('Estimates of the use of water ('!B:B,"Middle East & North Africa",'Estimates of the use of water ('!X:X) -> 0.12397804 | Y9: =AVERAGEIF('Estimates of the use of water ('!B:B,"Middle East & North Africa",'Estimates of the use of water ('!Q:Q) -> 0.73698723
B10: Total | C10: =SUM(C4:C9) -> 462 | I10: 2b | J10: How does the annual rate of change in water access differ between rural and urban populations? | U10: North America | V10: =COUNTIFS('Estimates of the use of water ('!B:B,"North America",'Estimates of the use of water ('!D:D,"<>")/2 -> 5 | W10: =AVERAGEIF('Estimates of the use of water ('!B:B,"North America",'Estimates of the use of water ('!E:E) -> 0.017158396 | X10: =AVERAGEIF('Estimates of the use of water ('!B:B,"North America",'Estimates of the use of water ('!X:X) -> 0.0020331735 | Y10: =AVERAGEIF('Estimates of the use of water ('!B:B,"North America",'Estimates of the use of water ('!Q:Q) -> 0.14233131
K13: Bin | L13: Lower | M13: Upper | N13: Count of countries | T13: 3b | U13: How do national and rural rates of change compare across regions and population sizes?
K14: -3.0 to -2.5 | L14: -3 | M14: -2.5 | N14: =COUNTIFS('Estimates of the use of water ('!$AB:$AB,">="&L14,'Estimates of the use of water ('!$AB:$AB,"<"&M14) -> 0
K15: -2.5 to -2.0 | L15: -2.5 | M15: -2 | N15: =COUNTIFS('Estimates of the use of water ('!$AB:$AB,">="&L15,'Estimates of the use of water ('!$AB:$AB,"<"&M15) -> 1
K16: -2.0 to -1.5 | L16: -2 | M16: -1.5 | N16: =COUNTIFS('Estimates of the use of water ('!$AB:$AB,">="&L16,'Estimates of the use of water ('!$AB:$AB,"<"&M16) -> 0
K17: -1.5 to -1.0 | L17: -1.5 | M17: -1 | N17: =COUNTIFS('Estimates of the use of water ('!$AB:$AB,">="&L17,'Estimates of the use of water ('!$AB:$AB,"<"&M17) -> 1
K18: -1.0 to -0.5 | L18: -1 | M18: -0.5 | N18: =COUNTIFS('Estimates of the use of water ('!$AB:$AB,">="&L18,'Estimates of the use of water ('!$AB:$AB,"<"&M18) -> 4
K19: -0.5 to 0.0 | L19: -0.5 | M19: 0 | N19: =COUNTIFS('Estimates of the use of water ('!$AB:$AB,">="&L19,'Estimates of the use of water ('!$AB:$AB,"<"&M19) -> 17
K20: 0.0 to 0.5 | L20: 0 | M20: 0.5 | N20: =COUNTIFS('Estimates of the use of water ('!$AB:$AB,">="&L20,'Estimates of the use of water ('!$AB:$AB,"<"&M20) -> 89
K21: 0.5 to 1.0 | L21: 0.5 | M21: 1 | N21: =COUNTIFS('Estimates of the use of water ('!$AB:$AB,">="&L21,'Estimates of the use of water ('!$AB:$AB,"<"&M21) -> 35
K22: 1.0 to 1.5 | L22: 1 | M22: 1.5 | N22: =COUNTIFS('Estimates of the use of water ('!$AB:$AB,">="&L22,'Estimates of the use of water ('!$AB:$AB,"<"&M22) -> 14
K23: 1.5 to 2.0 | L23: 1.5 | M23: 2 | N23: =COUNTIFS('Estimates of the use of water ('!$AB:$AB,">="&L23,'Estimates of the use of water ('!$AB:$AB,"<"&M23) -> 3
A24: 1b | B24: What is the average number of years between data collections per country? | K24: 2.0 to 2.5 | L24: 2 | M24: 2.5 | N24: =COUNTIFS('Estimates of the use of water ('!$AB:$AB,">="&L24,'Estimates of the use of water ('!$AB:$AB,"<"&M24) -> 1
K25: 2.5 to 3.0 | L25: 2.5 | M25: 3 | N25: =COUNTIFS('Estimates of the use of water ('!$AB:$AB,">="&L25,'Estimates of the use of water ('!$AB:$AB,"<"&M25) -> 0
B26: Average year dif | C26: Minimum Year diff | D26: Maximum year diff | K26: Total | N26: =SUM(N14:N25) -> 165
B27: =ROUND(AVERAGE('Estimates of the use of water ('!D:D),2) -> 4.8 | C27: =MIN('Estimates of the use of water ('!D:D) -> 1 | D27: =MAX('Estimates of the use of water ('!D:D) -> 5

Sheet Regions
A1: All countries + Regions | H1: Sub-Saharan Africa | M1: South Asia | R1: East Asia & Pacific | W1: Europe & Central Asia | AB1: Latin America & Caribbean | AG1: Middle East & North Africa | AL1: North America
A2: name | B2: region | C2: Arc n | D2: pop n | E2: Arc r | H2: country | I2: ARC_n | J2: ARC_r | K2: pop_n | M2: country | N2: ARC_n | O2: ARC_r | P2: pop_n | R2: country | S2: ARC_n | T2: ARC_r | U2: pop_n | W2: country | X2: ARC_n | Y2: ARC_r | Z2: pop_n | AB2: country | AC2: ARC_n | AD2: ARC_r | AE2: pop_n | AG2: country | AH2: ARC_n | AI2: ARC_r | AJ2: pop_n | AL2: country | AM2: ARC_n | AN2: ARC_r | AO2: pop_n
A3: Afghanistan | B3: South Asia | C3: =VLOOKUP($A3,'Estimates of the use of water ('!$A:$Q,5,FALSE) -> 2.7503265 | D3: =VLOOKUP($A3,'Estimates of the use of water ('!$A:$Q,6,FALSE) -> 34413.602 | E3: =VLOOKUP($A3,'Estimates of the use of water ('!$A:$Q,17,FALSE) -> 2.6678826 | H3: Angola | I3: 0.57016185 | J3: 0.21877144 | K3: 27884.381 | M3: Afghanistan | N3: 2.7503265 | O3: 2.6678826 | P3: 34413.602 | R3: Australia | S3: -3.877e-05 | T3: 0 | U3: 23932.498 | W3: Albania | X3: 0.3347427 | Y3: 0.69281669 | Z3: 2890.5239 | AB3: Belize | AC3: 0.24527193 | AD3: 0.4682751 | AE3: 360.92599 | AG3: Algeria | AH3: 0.20555369 | AI3: 0.33696621 | AJ3: 39728.02 | AL3: Canada | AM3: -0.001482146 | AN3: 0.048860164 | AO3: 36026.668
A4: Albania | B4: Europe & Central Asia | C4: =VLOOKUP($A4,'Estimates of the use of water ('!$A:$Q,5,FALSE) -> 0.3347427 | D4: =VLOOKUP($A4,'Estimates of the use of water ('!$A:$Q,6,FALSE) -> 2890.5239 | E4: =VLOOKUP($A4,'Estimates of the use of water ('!$A:$Q,17,FALSE) -> 0.69281669 | H4: Benin | I4: 0.12546014 | J4: 0.2535831 | K4: 10575.962 | M4: Bangladesh | N4: 0.11927156 | O4: 0.2214453 | P4: 156256.28 | R4: Cambodia | S4: 0.5552072 | T4: 0.47120783 | U4: 15521.435 | W4: Andorra | X4: 1.23e-06 | Y4: 0 | Z4: 77.992996 | AB4: Bolivia (Plurinational State of) | AC4: 0.58558612 | AD4: 1.2392925 | AE4: 10869.732 | AG4: Egypt | AH4: 0.066691684 | AI4: 0.10619145 | AJ4: 92442.547 | AL4: Greenland | AM4: 3.4e-07 | AN4: 0 | AO4: 56.377998
A5: Algeria | B5: Middle East & North Africa | C5: =VLOOKUP($A5,'Estimates of the use of water ('!$A:$Q,5,FALSE) -> 0.20555369 | D5: =VLOOKUP($A5,'Estimates of the use of water ('!$A:$Q,6,FALSE) -> 39728.02 | E5: =VLOOKUP($A5,'Estimates of the use of water ('!$A:$Q,17,FALSE) -> 0.33696621 | H5: Botswana | I5: 0.75345471 | J5: 1.430238 | K5: 2120.7161 | M5: Bhutan | N5: 0.21836001 | O5: 0.31336614 | P5: 727.88501 | R5: China | S5: 0.49969387 | T5: 1.0364091 | U5: 1430405.4 | W5: Armenia | X5: 0.083722798 | Y5: 0.18904415 | Z5: 2925.5591 | AB5: Brazil | AC5: 0.30345708 | AD5: 1.4378463 | AE5: 204471.77 | AG5: Iraq | AH5: 0.82246199 | AI5: 2.0136873 | AJ5: 35572.27 | AL5: United States of America | AM5: 0.087273784 | AN5: 0.37813377 | AO5: 320878.31
A6: American Samoa | B6: East Asia & Pacific | C6: =VLOOKUP($A6,'Estimates of the use of water ('!$A:$Q,5,FALSE) -> 0.030933702 | D6: =VLOOKUP($A6,'Estimates of the use of water ('!$A:$Q,6,FALSE) -> 55.806 | E6: =VLOOKUP($A6,'Estimates of the use of water ('!$A:$Q,17,FALSE) -> null | H6: Burkina Faso | I6: -0.58445533 | J6: -1.227381 | K6: 18110.615 | M6: India | N6: 0.47027848 | O6: 0.64210056 | P6: 1310152.4 | R6: Democratic People's Republic of Korea | S6: -0.27420774 | T6: -0.57266871 | U6: 25183.832 | W6: Austria | X6: 0 | Y6: 0 | Z6: 8678.667 | AB6: Chile | AC6: 0.0987012 | AD6: 0.5864603 | AE6: 17969.355 | AG6: Jordan | AH6: -0.01329639 | AI6: -0.01016734 | AJ6: 9266.5732
A7: Andorra | B7: Europe & Central Asia | C7: =VLOOKUP($A7,'Estimates of the use of water ('!$A:$Q,5,FALSE) -> 1.23e-06 | D7: =VLOOKUP($A7,'Estimates of the use of water ('!$A:$Q,6,FALSE) -> 77.992996 | E7: =VLOOKUP($A7,'Estimates of the use of water ('!$A:$Q,17,FALSE) -> 0 | H7: Burundi | I7: 0.5251306 | J7: 0.42549967 | K7: 10160.034 | M7: Iran (Islamic Republic of) | N7: 0.13512985 | O7: 0.33324655 | P7: 78492.211 | R7: Fiji | S7: 0.007701314 | T7: -0.058100668 | U7: 868.63202 | W7: Azerbaijan | X7: 0.72461243 | Y7: 1.3565169 | Z7: 9622.7412 | AB7: Colombia | AC7: 0.2311578 | AD7: 0.69866939 | AE7: 47520.668 | AG7: Morocco | AH7: 1.3302424 | AI7: 2.63472 | AJ7: 34663.609
A8: Angola | B8: Sub-Saharan Africa | C8: =VLOOKUP($A8,'Estimates of the use of water ('!$A:$Q,5,FALSE) -> 0.57016185 | D8: =VLOOKUP($A8,'Estimates of the use of water ('!$A:$Q,6,FALSE) -> 27884.381 | E8: =VLOOKUP($A8,'Estimates of the use of water ('!$A:$Q,17,FALSE) -> 0.21877144 | H8: Cabo Verde | I8: 0.66525281 | J8: 1.4564423 | K8: 524.73999 | M8: Malaysia | N8: 0.009540902 | O8: -0.14417222 | P8: 30270.965 | R8: Indonesia | S8: 0.77759933 | T8: 1.0074342 | U8: 258383.25 | W8: Belarus | X8: 0.011531798 | Y8: 0.046690142 | Z8: 9439.4238 | AB8: Costa Rica | AC8: 0.086370022 | AD8: 0.2920435 | AE8: 4847.8052 | AG8: Oman | AH8: 0.38590781 | AI8: 0.37677429 | AJ8: 4267.3408
A9: Anguilla | B9: Latin America & Caribbean | C9: =VLOOKUP($A9,'Estimates of the use of water ('!$A:$Q,5,FALSE) -> 0 | D9: =VLOOKUP($A9,'Estimates of the use of water ('!$A:$Q,6,FALSE) -> 14.279 | E9: =VLOOKUP($A9,'Estimates of the use of water ('!$A:$Q,17,FALSE) -> null | H9: Cameroon | I9: 0.34928561 | J9: 0.30438238 | K9: 23298.377 | M9: Maldives | N9: 0.14603886 | O9: 0.20786265 | P9: 454.914 | R9: Kiribati | S9: 0.82456485 | T9: 0.61438646 | U9: 110.927 | W9: Belgium | X9: -2.5e-07 | Y9: 0 | Z9: 11287.931 | AB9: Cuba | AC9: 0.22617994 | AD9: 0.7883181 | AE9: 11324.777 | AG9: Sudan | AH9: 0.29968446 | AI9: 0.29831787 | AJ9: 38902.949
A10: Antigua and Barbuda | B10: Latin America & Caribbean | C10: =VLOOKUP($A10,'Estimates of the use of water ('!$A:$Q,5,FALSE) -> 0 | D10: =VLOOKUP($A10,'Estimates of the use of water ('!$A:$Q,6,FALSE) -> 93.570999 | E10: =VLOOKUP($A10,'Estimates of the use of water ('!$A:$Q,17,FALSE) -> null | H10: Central African Republic | I10: -1.0217887 | J10: -0.75696273 | K10: 4493.1709 | M10: Nepal | N10: 0.45321484 | O10: 0.5922584 | P10: 27015.033 | R10: Lao People's Democratic Republic | S10: 1.5518342 | T10: 1.6466546 | U10: 6741.1602 | W10: Bosnia and Herzegovina | X10: -0.009189312 | Y10: 0 | Z10: 3429.3621 | AB10: Dominican Republic | AC10: 0.11749468 | AD10: 0.21868412 | AE10: 10281.675 | AG10: Syrian Arab Republic | AH10: 0.08324914 | AI10: 0.13940798 | AJ10: 17997.41
A11: Argentina | B11: Latin America & Caribbean | C11: =VLOOKUP($A11,'Estimates of the use of water ('!$A:$Q,5,FALSE) -> null | D11: =VLOOKUP($A11,'Estimates of the use of water ('!$A:$Q,6,FALSE) -> 43075.414 | E11: =VLOOKUP($A11,'Estimates of the use of water ('!$A:$Q,17,FALSE) -> null | H11: Chad | I11: 0.35768756 | J11: 0.3992629 | K11: 14110.971 | M11: Pakistan | N11: 0.13879655 | O11: 0.2897808 | P11: 199426.95 | R11: Marshall Islands | S11: 0.045904672 | T11: 0.030272 | U11: 57.444 | W11: Bulgaria | X11: -0.036982074 | Y11: -0.12297047 | Z11: 7199.7388 | AB11: Ecuador | AC11: 0.45919681 | AD11: 0.8996526 | AE11: 16212.022
A12: Armenia | B12: Europe & Central Asia | C12: =VLOOKUP($A12,'Estimates of the use of water ('!$A:$Q,5,FALSE) -> 0.083722798 | D12: =VLOOKUP($A12,'Estimates of the use of water ('!$A:$Q,6,FALSE) -> 2925.5591 | E12: =VLOOKUP($A12,'Estimates of the use of water ('!$A:$Q,17,FALSE) -> 0.18904415 | H12: Comoros | I12: 0.019624433 | J12: 0 | K12: 777.435 | M12: Philippines | N12: 0.41826671 | O12: 0.57075418 | P12: 102113.2 | R12: Mongolia | S12: 0.93652264 | T12: 1.7953726 | U12: 2998.4331 | W12: Cyprus | X12: -0.004668878 | Y12: -0.003084764 | Z12: 1160.9871 | AB12: El Salvador | AC12: 0.47688753 | AD12: 1.0986362 | AE12: 6325.1211
A13: Aruba | B13: Latin America & Caribbean | C13: =VLOOKUP($A13,'Estimates of the use of water ('!$A:$Q,5,FALSE) -> 0 | D13: =VLOOKUP($A13,'Estimates of the use of water ('!$A:$Q,6,FALSE) -> 104.339 | E13: =VLOOKUP($A13,'Estimates of the use of water ('!$A:$Q,17,FALSE) -> null | H13: Congo | I13: 0.52698596 | J13: 0.86651545 | K13: 4856.0928 | M13: Sri Lanka | N13: 0.42331016 | O13: 0.45606591 | P13: 20908.023 | R13: Myanmar | S13: 2.0261443 | T13: 2.2345902 | U13: 52680.723 | W13: Czech Republic | X13: 9.9796e-05 | Y13: 0 | Z13: 10601.39 | AB13: Falkland Islands (Malvinas) | AC13: 0.097784148 | AD13: 0 | AE13: 2.836
A14: Australia | B14: East Asia & Pacific | C14: =VLOOKUP($A14,'Estimates of the use of water ('!$A:$Q,5,FALSE) -> -3.877e-05 | D14: =VLOOKUP($A14,'Estimates of the use of water ('!$A:$Q,6,FALSE) -> 23932.498 | E14: =VLOOKUP($A14,'Estimates of the use of water ('!$A:$Q,17,FALSE) -> 0 | H14: Côte d'Ivoire | I14: -0.033339302 | J14: -0.024144972 | K14: 23226.148 | R14: New Zealand | S14: 7.9e-07 | T14: 0 | U14: 4614.5269 | W14: Denmark | X14: 6.5e-07 | Y14: 0 | Z14: 5688.6948 | AB14: Guatemala | AC14: 0.37447888 | AD14: 0.57531472 | AE14: 16252.425
A15: Austria | B15: Europe & Central Asia | C15: =VLOOKUP($A15,'Estimates of the use of water ('!$A:$Q,5,FALSE) -> 0 | D15: =VLOOKUP($A15,'Estimates of the use of water ('!$A:$Q,6,FALSE) -> 8678.667 | E15: =VLOOKUP($A15,'Estimates of the use of water ('!$A:$Q,17,FALSE) -> 0 | H15: Democratic Republic of the Congo | I15: 0.6467894 | J15: 0.27205571 | K15: 76244.531 | R15: Palau | S15: 0.00547893 | T15: 0.02862271 | U15: 17.665001 | W15: Finland | X15: 1.328e-06 | Y15: 0 | Z15: 5481.1279 | AB15: Guyana | AC15: 0.07858998 | AD15: 0.10114416 | AE15: 767.43298
A16: Azerbaijan | B16: Europe & Central Asia | C16: =VLOOKUP($A16,'Estimates of the use of water ('!$A:$Q,5,FALSE) -> 0.72461243 | D16: =VLOOKUP($A16,'Estimates of the use of water ('!$A:$Q,6,FALSE) -> 9622.7412 | E16: =VLOOKUP($A16,'Estimates of the use of water ('!$A:$Q,17,FALSE) -> 1.3565169 | H16: Djibouti | I16: 0.052575036 | J16: -0.29569443 | K16: 913.99799 | R16: Papua New Guinea | S16: 0.77170182 | T16: 0.81614213 | U16: 8107.772 | W16: France | X16: -3e-07 | Y16: 0 | Z16: 64453.195 | AB16: Honduras | AC16: 0.48696208 | AD16: 0.68774516 | AE16: 9112.9043
A17: Bahamas | B17: Latin America & Caribbean | C17: =VLOOKUP($A17,'Estimates of the use of water ('!$A:$Q,5,FALSE) -> 0 | D17: =VLOOKUP($A17,'Estimates of the use of water ('!$A:$Q,6,FALSE) -> 374.20001 | E17: =VLOOKUP($A17,'Estimates of the use of water ('!$A:$Q,17,FALSE) -> null | H17: Equatorial Guinea | I17: 0.2436072 | J17: 0 | K17: 1168.575 | R17: Samoa | S17: 0.10326544 | T17: 0.078781444 | U17: 193.50999 | W17: Georgia | X17: 0.31868204 | Y17: 0.59534672 | Z17: 4024.1799 | AB17: Jamaica | AC17: 0.12262964 | AD17: 0.17984045 | AE17: 2891.0239
A18: Bahrain | B18: Europe & Central Asia | C18: =VLOOKUP($A18,'Estimates of the use of water ('!$A:$Q,5,FALSE) -> 0 | D18: =VLOOKUP($A18,'Estimates of the use of water ('!$A:$Q,6,FALSE) -> 1371.853 | E18: =VLOOKUP($A18,'Estimates of the use of water ('!$A:$Q,17,FALSE) -> null | H18: Eritrea | I18: 0.38462665 | J18: 0 | K18: 3342.8181 | R18: Solomon Islands | S18: -0.40577867 | T18: -0.72137414 | U18: 603.133 | W18: Germany | X18: -1.9999999e-08 | Y18: 0 | Z18: 81787.414 | AB18: Mexico | AC18: 0.33082495 | AD18: 1.010075 | AE18: 121858.25
A19: Bangladesh | B19: South Asia | C19: =VLOOKUP($A19,'Estimates of the use of water ('!$A:$Q,5,FALSE) -> 0.11927156 | D19: =VLOOKUP($A19,'Estimates of the use of water ('!$A:$Q,6,FALSE) -> 156256.28 | E19: =VLOOKUP($A19,'Estimates of the use of water ('!$A:$Q,17,FALSE) -> 0.2214453 | H19: Eswatini | I19: 0.80982315 | J19: 0.86829277 | K19: 1104.038 | R19: Thailand | S19: 0.14816588 | T19: 0.22409666 | U19: 68714.516 | W19: Greece | X19: -4.6e-07 | Y19: 0 | Z19: 10659.737 | AB19: Nicaragua | AC19: 0.071125052 | AD19: -0.079442242 | AE19: 6223.2339
A20: Barbados | B20: Latin America & Caribbean | C20: =VLOOKUP($A20,'Estimates of the use of water ('!$A:$Q,5,FALSE) -> 0.008001136 | D20: =VLOOKUP($A20,'Estimates of the use of water ('!$A:$Q,6,FALSE) -> 285.327 | E20: =VLOOKUP($A20,'Estimates of the use of water ('!$A:$Q,17,FALSE) -> null | H20: Ethiopia | I20: 1.5091011 | J20: 1.5156744 | K20: 100835.45 | R20: Timor-Leste | S20: 2.0490995 | T20: 2.3056812 | U20: 1196.2939 | W20: Hungary | X20: 0.005893702 | Y20: 0.019982056 | Z20: 9777.9248 | AB20: Panama | AC20: 0.29363575 | AD20: 0.52870075 | AE20: 3968.49
A21: Belarus | B21: Europe & Central Asia | C21: =VLOOKUP($A21,'Estimates of the use of water ('!$A:$Q,5,FALSE) -> 0.011531798 | D21: =VLOOKUP($A21,'Estimates of the use of water ('!$A:$Q,6,FALSE) -> 9439.4238 | E21: =VLOOKUP($A21,'Estimates of the use of water ('!$A:$Q,17,FALSE) -> 0.046690142 | H21: Gabon | I21: 0.29668881 | J21: 0.27117117 | K21: 1947.6899 | R21: Tokelau | S21: 0.05005613 | T21: 0.05005613 | U21: 1.247 | W21: Iceland | X21: -1.018e-06 | Y21: 0 | Z21: 330.237 | AB21: Paraguay | AC21: 0.55145036 | AD21: 1.1533054 | AE21: 6688.7461
A22: Belgium | B22: Europe & Central Asia | C22: =VLOOKUP($A22,'Estimates of the use of water ('!$A:$Q,5,FALSE) -> -2.5e-07 | D22: =VLOOKUP($A22,'Estimates of the use of water ('!$A:$Q,6,FALSE) -> 11287.931 | E22: =VLOOKUP($A22,'Estimates of the use of water ('!$A:$Q,17,FALSE) -> 0 | H22: Gambia | I22: 0.34604813 | J22: 0.18672613 | K22: 2085.8601 | R22: Tonga | S22: 0.036275096 | T22: 0.015006062 | U22: 100.78 | W22: Ireland | X22: 0.005515704 | Y22: 0.023620912 | Z22: 4652.4199 | AB22: Peru | AC22: 0.57147263 | AD22: 1.5023629 | AE22: 30470.738
