Workbook

Sheet Overview
A1: Introduction
A3: Aim
A4: Investigate access to safe and affordable drinking water focussing on service levels between different country or regions
A6: Data Dictionary
A7: name | B7: The country or area name.
A8: income_group | B8: The country’s classification according to income group.
A9: pop_n | B9: The national population size estimate, in thousands.
A10: pop_u | B10: The urban population share estimate in percentage points (%)
A11: pop_r | B11: The rural population share estimate in percentage points (%)
A12: wat_lim_n | B12: The estimated national share of people with limited service (%).
A13: wat_lim_u | B13: The estimated urban share of people with limited service (%).
A14: wat_lim_r | B14: The estimated rural share of people with limited service (%).
A15: wat_unimp_n | B15: The estimated national share of people with unimproved service (%)
A16: wat_unimp_u | B16: The estimated urban share of people with unimproved service (%)
A17: wat_unimp_r | B17: The estimated rural share of people with unimproved service (%).
A18: wat_sur_n | B18: The estimated national share of people with surface service (%).
... A23: wat_bas_r | B23: The estimated rural share of people with at least basic service (%).
A26: Research Questions
A27: 1 | B27: How do the world population estimates compare to the provided data set?
A28: 2 | B28: How does urban population share compare to rural?
A29: 3 | B29: What is the tendency and spread of the different access features?
A30: 4 | B30: What is the effect of national population size and urbanisation on gross national income and water access?
A33: Key Findings
A34: 1 | B34: The dataset covers 99.6% of the world's population (only a 0.44% difference from the theoretical total), a reliable basis for global level conclusions.
A35: 2 | B35: 56% of the population is urban vs. 44% rural.
A36: 3 | B36: Basic water access is left-skewed. The mean sits below the mode for all areas (national mean 89.5 vs. mode 100, rural mean 80.1 vs. mode 100, urban mean 92.8 vs. mode 100), meaning most countries have full access, but a smaller group with much lower access pulls the average down.
B37: Rural basic access has the widest spread (IQR of 35.76, minimum of 5.22), compared to urban (IQR of 8.13, minimum of 0.14 but Q1 of 91.82). This shows urban areas are consistently close to full access, while rural access varies enormously across countries
B38: Limited, unimproved, and surface water access are all right-skewed with a mode of 0. Most countries report close to none of their population using these poorer service levels, but a smaller group of countries have much higher shares, up to 51% for unimproved rural access and up to 94% for surface water nationally.
A39: 4 | B39: Predictors of access: Population size and urbanization show no clear relationship with water access. Income group is the strongest predictor, high income countries average near 100% basic access, low income countries average about 65%.
A42: Recommendations
A43: 1 | B43: Prioritize rural water infrastructure, since rural access is the lowest and most inconsistent globally.
A44: 2 | B44: Target support toward low income countries, since income group, not population size or urbanization, is the strongest driver of access.

Sheet Data_Estimates-on-the-use-of-wa
B1: income_group | C1: pop_n | D1: pop_n_(m) | E1: pop_u | F1: pop_u_rounded | G1: pop_u_val | H1: pop_r | I1: pop_r_rounded | J1: wat_bas_n | K1: wat_bas_n (rounded) | L1: wat_lim_n | M1: wat_unimp_n | N1: wat_sur_n | O1: wat_bas_r | P1: wat_lim_r | Q1: wat_unimp_r | R1: wat_sur_r | S1: wat_bas_u | T1: wat_lim_u | U1: wat_unimp_u | V1: wat_sur_u | W1: value_cnt
A2: Saint Barthelemy | B2: NAN | C2: 9.885 | D2: =ROUNDUP(C2/1000,0) -> 1 | E2: 100 | F2: =ROUND(E2,0) -> 100 | G2: =C2*(E2/100) -> 9.885 | H2: =100-E2 -> 0 | I2: =ROUND(H2,0) -> 0 | J2: 100 | K2: =ROUND(J2,1) -> 100 | L2: 0 | M2: 0 | N2: 0 | O2: NAN | P2: NAN | Q2: NAN | R2: NAN | S2: 100 | T2: 0 | U2: 0 | V2: 0 | W2: =COUNTA(A2:V2) -> 22
A3: Nauru | B3: High income | C3: 10.834 | D3: =ROUNDUP(C3/1000,0) -> 1 | E3: 100 | F3: =ROUND(E3,0) -> 100 | G3: =C3*(E3/100) -> 10.834 | H3: =100-E3 -> 0 | I3: =ROUND(H3,0) -> 0 | J3: 100 | K3: =ROUND(J3,1) -> 100 | L3: 0 | M3: 0 | N3: 0 | O3: NAN | P3: NAN | Q3: NAN | R3: NAN | S3: 100 | T3: 0 | U3: 0 | V3: 0 | W3: =COUNTA(A3:V3) -> 22
A4: Gibraltar | B4: High income | C4: 33.691002 | D4: =ROUNDUP(C4/1000,0) -> 1 | E4: 100 | F4: =ROUND(E4,0) -> 100 | G4: =C4*(E4/100) -> 33.691002 | H4: =100-E4 -> 0 | I4: =ROUND(H4,0) -> 0 | J4: 100 | K4: =ROUND(J4,1) -> 100 | L4: 0 | M4: 0 | N4: 0 | O4: NAN | P4: NAN | Q4: NAN | R4: NAN | S4: 100 | T4: 0 | U4: 0 | V4: 0 | W4: =COUNTA(A4:V4) -> 22
A5: Saint Martin (French part) | B5: High income | C5: 38.659 | D5: =ROUNDUP(C5/1000,0) -> 1 | E5: 100 | F5: =ROUND(E5,0) -> 100 | G5: =C5*(E5/100) -> 38.659 | H5: =100-E5 -> 0 | I5: =ROUND(H5,0) -> 0 | J5: 99.999271 | K5: =ROUND(J5,1) -> 100 | L5: 0 | M5: 0.00072861055 | N5: 0 | O5: NAN | P5: NAN | Q5: NAN | R5: NAN | S5: 99.999271 | T5: 0 | U5: 0.00072861055 | V5: 0 | W5: =COUNTA(A5:V5) -> 22
A6: Monaco | B6: High income | C6: 39.243999 | D6: =ROUNDUP(C6/1000,0) -> 1 | E6: 100 | F6: =ROUND(E6,0) -> 100 | G6: =C6*(E6/100) -> 39.243999 | H6: =100-E6 -> 0 | I6: =ROUND(H6,0) -> 0 | J6: 100 | K6: =ROUND(J6,1) -> 100 | L6: 0 | M6: 0 | N6: 0 | O6: NAN | P6: NAN | Q6: NAN | R6: NAN | S6: 100 | T6: 0 | U6: 0 | V6: 0 | W6: =COUNTA(A6:V6) -> 22
A7: Bermuda | B7: High income | C7: 62.272999 | D7: =ROUNDUP(C7/1000,0) -> 1 | E7: 100 | F7: =ROUND(E7,0) -> 100 | G7: =C7*(E7/100) -> 62.272999 | H7: =100-E7 -> 0 | I7: =ROUND(H7,0) -> 0 | J7: 99.90314 | K7: =ROUND(J7,1) -> 99.9 | L7: 0 | M7: 0.096859983 | N7: 0 | O7: NAN | P7: NAN | Q7: NAN | R7: NAN | S7: 99.90314 | T7: 0 | U7: 0.096859983 | V7: 0 | W7: =COUNTA(A7:V7) -> 22
A8: China, Macao SAR | B8: High income | C8: 649.34198 | D8: =ROUNDUP(C8/1000,0) -> 1 | E8: 100 | F8: =ROUND(E8,0) -> 100 | G8: =C8*(E8/100) -> 649.34198 | H8: =100-E8 -> 0 | I8: =ROUND(H8,0) -> 0 | J8: 100 | K8: =ROUND(J8,1) -> 100 | L8: 0 | M8: 0 | N8: 0 | O8: NAN | P8: NAN | Q8: NAN | R8: NAN | S8: 100 | T8: 0 | U8: 0 | V8: 0 | W8: =COUNTA(A8:V8) -> 22
A9: Réunion | B9: NAN | C9: 895.30798 | D9: =ROUNDUP(C9/1000,0) -> 1 | E9: 99.659004 | F9: =ROUND(E9,0) -> 100 | G9: =C9*(E9/100) -> 892.25502 | H9: =100-E9 -> 0.34099579 | I9: =ROUND(H9,0) -> 0 | J9: 100 | K9: =ROUND(J9,1) -> 100 | L9: 0 | M9: 0 | N9: 0 | O9: NAN | P9: NAN | Q9: NAN | R9: NAN | S9: NAN | T9: NAN | U9: NAN | V9: NAN | W9: =COUNTA(A9:V9) -> 22
A10: Guadeloupe | B10: NAN | C10: 400.12701 | D10: =ROUNDUP(C10/1000,0) -> 1 | E10: 98.498993 | F10: =ROUND(E10,0) -> 98 | G10: =C10*(E10/100) -> 394.12108 | H10: =100-E10 -> 1.5010071 | I10: =ROUND(H10,0) -> 2 | J10: 99.803126 | K10: =ROUND(J10,1) -> 99.8 | L10: 0 | M10: 0.19687396 | N10: 0 | O10: NAN | P10: NAN | Q10: NAN | R10: NAN | S10: NAN | T10: NAN | U10: NAN | V10: NAN | W10: =COUNTA(A10:V10) -> 22
A11: San Marino | B11: High income | C11: 33.938 | D11: =ROUNDUP(C11/1000,0) -> 1 | E11: 97.499001 | F11: =ROUND(E11,0) -> 97 | G11: =C11*(E11/100) -> 33.089211 | H11: =100-E11 -> 2.5009995 | I11: =ROUND(H11,0) -> 3 | J11: 100 | K11: =ROUND(J11,1) -> 100 | L11: 0 | M11: 0 | N11: 0 | O11: NAN | P11: NAN | Q11: NAN | R11: NAN | S11: NAN | T11: NAN | U11: NAN | V11: NAN | W11: =COUNTA(A11:V11) -> 22
A12: United States Virgin Islands | B12: High income | C12: 104.423 | D12: =ROUNDUP(C12/1000,0) -> 1 | E12: 95.939003 | F12: =ROUND(E12,0) -> 96 | G12: =C12*(E12/100) -> 100.18238 | H12: =100-E12 -> 4.060997 | I12: =ROUND(H12,0) -> 4 | J12: 98.718267 | K12: =ROUND(J12,1) -> 98.7 | L12: 0 | M12: 1.2817326 | N12: 0 | O12: NAN | P12: NAN | Q12: NAN | R12: NAN | S12: NAN | T12: NAN | U12: NAN | V12: NAN | W12: =COUNTA(A12:V12) -> 22
A13: Guam | B13: High income | C13: 168.783 | D13: =ROUNDUP(C13/1000,0) -> 1 | E13: 94.938004 | F13: =ROUND(E13,0) -> 95 | G13: =C13*(E13/100) -> 160.23922 | H13: =100-E13 -> 5.0619965 | I13: =ROUND(H13,0) -> 5 | J13: 99.6952 | K13: =ROUND(J13,1) -> 99.7 | L13: 0 | M13: 0.3048 | N13: 0 | O13: NAN | P13: NAN | Q13: NAN | R13: NAN | S13: NAN | T13: NAN | U13: NAN | V13: NAN | W13: =COUNTA(A13:V13) -> 22
A14: Malta | B14: High income | C14: 441.539 | D14: =ROUNDUP(C14/1000,0) -> 1 | E14: 94.744003 | F14: =ROUND(E14,0) -> 95 | G14: =C14*(E14/100) -> 418.33173 | H14: =100-E14 -> 5.2559967 | I14: =ROUND(H14,0) -> 5 | J14: 100 | K14: =ROUND(J14,1) -> 100 | L14: 0 | M14: 0 | N14: 0 | O14: 100 | P14: 0 | Q14: 0 | R14: 0 | S14: 100 | T14: 0 | U14: 0 | V14: 0 | W14: =COUNTA(A14:V14) -> 22
A15: Iceland | B15: High income | C15: 341.25 | D15: =ROUNDUP(C15/1000,0) -> 1 | E15: 93.897995 | F15: =ROUND(E15,0) -> 94 | G15: =C15*(E15/100) -> 320.42691 | H15: =100-E15 -> 6.102005 | I15: =ROUND(H15,0) -> 6 | J15: 99.999997 | K15: =ROUND(J15,1) -> 100 | L15: 0 | M15: 2.79465e-06 | N15: 0 | O15: 100 | P15: 0 | Q15: 0 | R15: 0 | S15: 100 | T15: 0 | U15: 0 | V15: 0 | W15: =COUNTA(A15:V15) -> 22
A16: Northern Mariana Islands | B16: High income | C16: 57.556999 | D16: =ROUNDUP(C16/1000,0) -> 1 | E16: 91.797997 | F16: =ROUND(E16,0) -> 92 | G16: =C16*(E16/100) -> 52.836172 | H16: =100-E16 -> 8.2020035 | I16: =ROUND(H16,0) -> 8 | J16: 100 | K16: =ROUND(J16,1) -> 100 | L16: 0 | M16: 0 | N16: 0 | O16: NAN | P16: NAN | Q16: NAN | R16: NAN | S16: NAN | T16: NAN | U16: NAN | V16: NAN | W16: =COUNTA(A16:V16) -> 22
A17: Luxembourg | B17: High income | C17: 625.97601 | D17: =ROUNDUP(C17/1000,0) -> 1 | E17: 91.452995 | F17: =ROUND(E17,0) -> 91 | G17: =C17*(E17/100) -> 572.47381 | H17: =100-E17 -> 8.5470047 | I17: =ROUND(H17,0) -> 9 | J17: 99.879933 | K17: =ROUND(J17,1) -> 99.9 | L17: 0 | M17: 0.12006746 | N17: 0 | O17: 98.595238 | P17: 0 | Q17: 1.4047619 | R17: 0 | S17: 100 | T17: 0 | U17: 0 | V17: 0 | W17: =COUNTA(A17:V17) -> 22
A18: Saint Pierre and Miquelon | B18: NAN | C18: 5.7950001 | D18: =ROUNDUP(C18/1000,0) -> 1 | E18: 89.961998 | F18: =ROUND(E18,0) -> 90 | G18: =C18*(E18/100) -> 5.2132979 | H18: =100-E18 -> 10.038002 | I18: =ROUND(H18,0) -> 10 | J18: 91.4 | K18: =ROUND(J18,1) -> 91.4 | L18: 0 | M18: 8.6 | N18: 0 | O18: NAN | P18: NAN | Q18: NAN | R18: NAN | S18: NAN | T18: NAN | U18: NAN | V18: NAN | W18: =COUNTA(A18:V18) -> 22
A19: Marshall Islands | B19: Upper middle income | C19: 59.194 | D19: =ROUNDUP(C19/1000,0) -> 1 | E19: 88.572047 | F19: =ROUND(E19,0) -> 89 | G19: =C19*(E19/100) -> 52.429338 | H19: =100-E19 -> 11.427953 | I19: =ROUND(H19,0) -> 11 | J19: 11.387979 | K19: =ROUND(J19,1) -> 11.4 | L19: 0.039974026 | M19: 0 | N19: 94.42972 | O19: 5.39028 | P19: 0.18 | Q19: 0 | R19: 86.9 | S19: 13.1 | T19: 0 | U19: 0 | V19: NAN | W19: =COUNTA(A19:V19) -> 22
A20: Martinique | B20: NAN | C20: 375.26501 | D20: =ROUNDUP(C20/1000,0) -> 1 | E20: 89.139999 | F20: =ROUND(E20,0) -> 89 | G20: =C20*(E20/100) -> 334.51123 | H20: =100-E20 -> 10.860001 | I20: =ROUND(H20,0) -> 11 | J20: 99.841971 | K20: =ROUND(J20,1) -> 99.8 | L20: 0 | M20: 0.15802922 | N20: 0 | O20: NAN | P20: NAN | Q20: NAN | R20: NAN | S20: NAN | T20: NAN | U20: NAN | V20: NAN | W20: =COUNTA(A20:V20) -> 22
A21: Andorra | B21: High income | C21: 77.264999 | D21: =ROUNDUP(C21/1000,0) -> 1 | E21: 87.916 | F21: =ROUND(E21,0) -> 88 | G21: =C21*(E21/100) -> 67.928297 | H21: =100-E21 -> 12.084 | I21: =ROUND(H21,0) -> 12 | J21: 100 | K21: =ROUND(J21,1) -> 100 | L21: 0 | M21: 0 | N21: 0 | O21: 100 | P21: 0 | Q21: 0 | R21: 0 | S21: 100 | T21: 0 | U21: 0 | V21: 0 | W21: =COUNTA(A21:V21) -> 22
A22: American Samoa | B22: Upper middle income | C22: 55.196999 | D22: =ROUNDUP(C22/1000,0) -> 1 | E22: 87.153 | F22: =ROUND(E22,0) -> 87 | G22: =C22*(E22/100) -> 48.10584 | H22: =100-E22 -> 12.847 | I22: =ROUND(H22,0) -> 13 | J22: 99.773772 | K22: =ROUND(J22,1) -> 99.8 | L22: 0 | M22: 0.22622834 | N22: 0 | O22: NAN | P22: NAN | Q22: NAN | R22: NAN | S22: NAN | T22: NAN | U22: NAN | V22: NAN | W22: =COUNTA(A22:V22) -> 22
A23: Greenland | B23: High income | C23: 56.771999 | D23: =ROUNDUP(C23/1000,0) -> 1 | E23: 87.282005 | F23: =ROUND(E23,0) -> 87 | G23: =C23*(E23/100) -> 49.551739 | H23: =100-E23 -> 12.717995 | I23: =ROUND(H23,0) -> 13 | J23: 100 | K23: =ROUND(J23,1) -> 100 | L23: 0 | M23: 0 | N23: 0 | O23: 100 | P23: 0 | Q23: 0 | R23: 0 | S23: 100 | T23: 0 | U23: 0 | V23: 0 | W23: =COUNTA(A23:V23) -> 22
A24: French Guiana | B24: NAN | C24: 298.68201 | D24: =ROUNDUP(C24/1000,0) -> 1 | E24: 85.82 | F24: =ROUND(E24,0) -> 86 | G24: =C24*(E24/100) -> 256.3289 | H24: =100-E24 -> 14.18 | I24: =ROUND(H24,0) -> 14 | J24: 93.782216 | K24: =ROUND(J24,1) -> 93.8 | L24: 0 | M24: 6.2177837 | N24: 0 | O24: NAN | P24: NAN | Q24: NAN | R24: NAN | S24: NAN | T24: NAN | U24: NAN | V24: NAN | W24: =COUNTA(A24:V24) -> 22
A25: Palau | B25: Upper middle income | C25: 18.091999 | D25: =ROUNDUP(C25/1000,0) -> 1 | E25: 80.987999 | F25: =ROUND(E25,0) -> 81 | G25: =C25*(E25/100) -> 14.652348 | H25: =100-E25 -> 19.012001 | I25: =ROUND(H25,0) -> 19 | J25: 99.657545 | K25: =ROUND(J25,1) -> 99.7 | L25: 0 | M25: 0.3424545 | N25: 0 | O25: 99.756985 | P25: 0 | Q25: 0.24301497 | R25: 0 | S25: 99.634202 | T25: 0 | U25: 0.36579801 | V25: 0 | W25: =COUNTA(A25:V25) -> 22
A26: Falkland Islands (Malvinas) | B26: NAN | C26: 3.483 | D26: =ROUNDUP(C26/1000,0) -> 1 | E26: 78.507996 | F26: =ROUND(E26,0) -> 79 | G26: =C26*(E26/100) -> 2.7344335 | H26: =100-E26 -> 21.492004 | I26: =ROUND(H26,0) -> 21 | J26: 95.308927 | K26: =ROUND(J26,1) -> 95.3 | L26: 0 | M26: 4.6910726 | N26: 0 | O26: 78.172943 | P26: 0 | Q26: 21.827057 | R26: 0 | S26: 100 | T26: 0 | U26: 0 | V26: 0 | W26: =COUNTA(A26:V26) -> 22
A27: Brunei Darussalam | B27: High income | C27: 437.483 | D27: =ROUNDUP(C27/1000,0) -> 1 | E27: 78.250008 | F27: =ROUND(E27,0) -> 78 | G27: =C27*(E27/100) -> 342.33048 | H27: =100-E27 -> 21.749992 | I27: =ROUND(H27,0) -> 22 | J27: 99.900037 | K27: =ROUND(J27,1) -> 99.9 | L27: 0 | M27: 0.0999632 | N27: 0 | O27: NAN | P27: NAN | Q27: NAN | R27: NAN | S27: 99.65 | T27: 0 | U27: 0.35 | V27: 0 | W27: =COUNTA(A27:V27) -> 22
A28: Djibouti | B28: Lower middle income | C28: 988.00201 | D28: =ROUNDUP(C28/1000,0) -> 1 | E28: 78.061996 | F28: =ROUND(E28,0) -> 78 | G28: =C28*(E28/100) -> 771.2541 | H28: =100-E28 -> 21.938004 | I28: =ROUND(H28,0) -> 22 | J28: 76.04992 | K28: =ROUND(J28,1) -> 76 | L28: 14.757482 | M28: 7.0158761 | N28: 2.176722 | O28: 47.280733 | P28: 12.06161 | Q28: 30.735505 | R28: 9.9221522 | S28: 84.135015 | T28: 15.515111 | U28: 0.349874 | V28: 0 | W28: =COUNTA(A28:V28) -> 22
A29: Cook Islands | B29: NAN | C29: 17.563999 | D29: =ROUNDUP(C29/1000,0) -> 1 | E29: 75.495003 | F29: =ROUND(E29,0) -> 75 | G29: =C29*(E29/100) -> 13.259942 | H29: =100-E29 -> 24.504997 | I29: =ROUND(H29,0) -> 25 | J29: 99.97161 | K29: =ROUND(J29,1) -> 100 | L29: 0 | M29: 0.028389783 | N29: 0 | O29: NAN | P29: NAN | Q29: NAN | R29: NAN | S29: NAN | T29: NAN | U29: NAN | V29: NAN | W29: =COUNTA(A29:V29) -> 22
A30: Sao Tome and Principe | B30: Lower middle income | C30: 219.161 | D30: =ROUNDUP(C30/1000,0) -> 1 | E30: 74.354004 | F30: =ROUND(E30,0) -> 74 | G30: =C30*(E30/100) -> 162.95498 | H30: =100-E30 -> 25.645996 | I30: =ROUND(H30,0) -> 26 | J30: 78.226455 | K30: =ROUND(J30,1) -> 78.2 | L30: 20.237983 | M30: 0.44351993 | N30: 1.0920419 | O30: 74.300614 | P30: 19.711843 | Q30: 1.7294057 | R30: 4.2581372 | S30: 79.580543 | T30: 20.419457 | U30: 0 | V30: 0 | W30: =COUNTA(A30:V30) -> 22
A31: New Caledonia | B31: High income | C31: 285.491 | D31: =ROUNDUP(C31/1000,0) -> 1 | E31: 71.517998 | F31: =ROUND(E31,0) -> 72 | G31: =C31*(E31/100) -> 204.17745 | H31: =100-E31 -> 28.482002 | I31: =ROUND(H31,0) -> 28 | J31: 99.305321 | K31: =ROUND(J31,1) -> 99.3 | L31: 0 | M31: 0.69467943 | N31: 0 | O31: NAN | P31: NAN | Q31: NAN | R31: NAN | S31: NAN | T31: NAN | U31: NAN | V31: NAN | W31: =COUNTA(A31:V31) -> 22
A32: Cabo Verde | B32: Lower middle income | C32: 555.98798 | D32: =ROUNDUP(C32/1000,0) -> 1 | E32: 66.652 | F32: =ROUND(E32,0) -> 67 | G32: =C32*(E32/100) -> 370.57711 | H32: =100-E32 -> 33.348 | I32: =ROUND(H32,0) -> 33 | J32: 88.769606 | K32: =ROUND(J32,1) -> 88.8 | L32: 3.2091477 | M32: 0.11709501 | N32: 80.114525 | O32: 9.911127 | P32: 9.623217 | Q32: 0.35113054 | R32: 93.1 | S32: 6.9 | T32: 0 | U32: 0 | V32: NAN | W32: =COUNTA(A32:V32) -> 22
A33: Montenegro | B33: Upper middle income | C33: 628.06201 | D33: =ROUNDUP(C33/1000,0) -> 1 | E33: 67.488007 | F33: =ROUND(E33,0) -> 67 | G33: =C33*(E33/100) -> 423.86653 | H33: =100-E33 -> 32.511993 | I33: =ROUND(H33,0) -> 33 | J33: 98.856917 | K33: =ROUND(J33,1) -> 98.9 | L33: 0.54547882 | M33: 0.59231201 | N33: 0.0052926509 | O33: 98.161888 | P33: 0 | Q33: 1.8218334 | R33: 0.01627907 | S33: 99.19174 | T33: 0.80826041 | U33: 0 | V33: 0 | W33: =COUNTA(A33:V33) -> 22
A34: Suriname | B34: Upper middle income | C34: 586.63397 | D34: =ROUNDUP(C34/1000,0) -> 1 | E34: 66.149002 | F34: =ROUND(E34,0) -> 66 | G34: =C34*(E34/100) -> 388.05252 | H34: =100-E34 -> 33.850998 | I34: =ROUND(H34,0) -> 34 | J34: 97.989632 | K34: =ROUND(J34,1) -> 98 | L34: 1.0672469 | M34: 0.37933651 | N34: 0.56378488 | O34: 96.574413 | P34: 1.6002959 | Q34: 0.15980179 | R34: 1.6654897 | S34: 98.713854 | T34: 0.79446524 | U34: 0.49168089 | V34: 0 | W34: =COUNTA(A34:V34) -> 22
A35: Tuvalu | B35: Upper middle income | C35: 11.792 | D35: =ROUNDUP(C35/1000,0) -> 1 | E35: 64.014 | F35: =ROUND(E35,0) -> 64 | G35: =C35*(E35/100) -> 7.5485308 | H35: =100-E35 -> 35.986 | I35: =ROUND(H35,0) -> 36 | J35: 100 | K35: =ROUND(J35,1) -> 100 | L35: 0 | M35: 0 | N35: 0 | O35: 100 | P35: 0 | Q35: 0 | R35: 0 | S35: 100 | T35: 0 | U35: 0 | V35: 0 | W35: =COUNTA(A35:V35) -> 22
A36: French Polynesia | B36: High income | C36: 280.90399 | D36: =ROUNDUP(C36/1000,0) -> 1 | E36: 61.975002 | F36: =ROUND(E36,0) -> 62 | G36: =C36*(E36/100) -> 174.09026 | H36: =100-E36 -> 38.024998 | I36: =ROUND(H36,0) -> 38 | J36: 100 | K36: =ROUND(J36,1) -> 100 | L36: 0 | M36: 0 | N36: 0 | O36: NAN | P36: NAN | Q36: NAN | R36: NAN | S36: NAN | T36: NAN | U36: NAN | V36: NAN | W36: =COUNTA(A36:V36) -> 22
A37: Fiji | B37: Upper middle income | C37: 896.44397 | D37: =ROUNDUP(C37/1000,0) -> 1 | E37: 57.247005 | F37: =ROUND(E37,0) -> 57 | G37: =C37*(E37/100) -> 513.18733 | H37: =100-E37 -> 42.752995 | I37: =ROUND(H37,0) -> 43 | J37: 94.301065 | K37: =ROUND(J37,1) -> 94.3 | L37: 0 | M37: 3.3186028 | N37: 2.380332 | O37: 89.088024 | P37: 0 | Q37: 5.7598979 | R37: 5.152078 | S37: 98.194244 | T37: 0 | U37: 1.4954093 | V37: 0.31034659 | W37: =COUNTA(A37:V37) -> 22
A38: Kiribati | B38: Lower middle income | C38: 119.446 | D38: =ROUNDUP(C38/1000,0) -> 1 | E38: 55.593998 | F38: =ROUND(E38,0) -> 56 | G38: =C38*(E38/100) -> 66.404806 | H38: =100-E38 -> 44.406002 | I38: =ROUND(H38,0) -> 44 | J38: 77.970921 | K38: =ROUND(J38,1) -> 78 | L38: 4.0768996 | M38: 17.95218 | N38: 0 | O38: 60.994185 | P38: 2.0966098 | Q38: 36.909205 | R38: 0 | S38: 91.531175 | T38: 5.6586665 | U38: 2.8101587 | V38: 0 | W38: =COUNTA(A38:V38) -> 22
A39: Isle of Man | B39: High income | C39: 85.031998 | D39: =ROUNDUP(C39/1000,0) -> 1 | E39: 52.898003 | F39: =ROUND(E39,0) -> 53 | G39: =C39*(E39/100) -> 44.980228 | H39: =100-E39 -> 47.101997 | I39: =ROUND(H39,0) -> 47 | J39: 99.075 | K39: =ROUND(J39,1) -> 99.1 | L39: 0 | M39: 0.925 | N39: 0 | O39: NAN | P39: NAN | Q39: NAN | R39: NAN | S39: NAN | T39: NAN | U39: NAN | V39: NAN | W39: =COUNTA(A39:V39) -> 22
A40: British Virgin Islands | B40: High income | C40: 30.237 | D40: =ROUNDUP(C40/1000,0) -> 1 | E40: 48.514999 | F40: =ROUND(E40,0) -> 49 | G40: =C40*(E40/100) -> 14.66948 | H40: =100-E40 -> 51.485001 | I40: =ROUND(H40,0) -> 51 | J40: 99.864384 | K40: =ROUND(J40,1) -> 99.9 | L40: 0 | M40: 0.13561644 | N40: 0 | O40: NAN | P40: NAN | Q40: NAN | R40: NAN | S40: NAN | T40: NAN | U40: NAN | V40: NAN | W40: =COUNTA(A40:V40) -> 22
...

Sheet  Report
A1: 1 | B1: How do the world population estimates compare to the provided data set? | G1: 3 | H1: What is the tendency and spread of the different access features? | Q1: 3b | R1: How is the spread of access compare over different types of areas?
B3: total pop (theoretical) | C3: total pop_n_calculated | D3: pop percent difference
B4: 7821000000 | C4: ='Pivot Table 1'!X3*1000 -> 7786695108 | D4: =ABS(B4-C4)/((B4+C4)/2)*100 -> 0.43958947 | H4: Feature | I4: Min | J4: Q1 | K4: Q3 | L4: Max | M4: Mode | N4: Mean | O4: IQR
H5: wat_bas_n | I5: =min('Data_Estimates-on-the-use-of-wa'!J:J) -> 11.387979 | J5: =QUARTILE('Data_Estimates-on-the-use-of-wa'!J:J,1) -> 85.495613 | K5: =QUARTILE('Data_Estimates-on-the-use-of-wa'!J:J,3) -> 99.887525 | L5: 100 | M5: =MODE('Data_Estimates-on-the-use-of-wa'!J:J) -> 100 | N5: =AVERAGE('Data_Estimates-on-the-use-of-wa'!J:J) -> 89.498981 | O5: =K5-J5 -> 14.391912
A6: 2 | B6: How does urban population share compare to rural? | H6: wat_lim_n | I6: =Min('Data_Estimates-on-the-use-of-wa'!L:L) -> 0 | J6: =quartile('Data_Estimates-on-the-use-of-wa'!L:L,1) -> 0 | K6: =QUARTILE('Data_Estimates-on-the-use-of-wa'!L:L,3) -> 4.1605495 | L6: =max('Data_Estimates-on-the-use-of-wa'!L:L) -> 37.426963 | M6: =MODE('Data_Estimates-on-the-use-of-wa'!L:L) -> 0 | N6: =AVERAGE('Data_Estimates-on-the-use-of-wa'!L:L) -> 3.7892321 | O6: =K6-J6 -> 4.1605495
H7: wat_unimp_n | I7: =min('Data_Estimates-on-the-use-of-wa'!M:M) -> 0 | J7: =QUARTILE('Data_Estimates-on-the-use-of-wa'!M:M,1) -> 0.031798312 | K7: =QUARTILE('Data_Estimates-on-the-use-of-wa'!M:M,3) -> 5.2793099 | L7: =max('Data_Estimates-on-the-use-of-wa'!M:M) -> 33.539114 | M7: =MODE('Data_Estimates-on-the-use-of-wa'!M:M) -> 0 | N7: =AVERAGE('Data_Estimates-on-the-use-of-wa'!M:M) -> 4.4031669 | O7: =K7-J7 -> 5.2475116
B8: pop _u calculated | C8: pop_rural_calculated | D8: percent urban | E8: percent rural | H8: wat_sur_n | I8: =min('Data_Estimates-on-the-use-of-wa'!N:N) -> 0 | J8: =QUARTILE('Data_Estimates-on-the-use-of-wa'!N:N,1) -> 0 | K8: =QUARTILE('Data_Estimates-on-the-use-of-wa'!N:N,3) -> 1.9898353 | L8: =max('Data_Estimates-on-the-use-of-wa'!N:N) -> 94.42972 | M8: =mode('Data_Estimates-on-the-use-of-wa'!N:N) -> 0 | N8: =average('Data_Estimates-on-the-use-of-wa'!N:N) -> 2.7841715 | O8: =K8-J8 -> 1.9898353
B9: ='Pivot Table 1'!Y3*1000 -> 4375314843 | C9: =C4-B9 -> 3411380265 | D9: =B9/C4*100 -> 56.189626 | E9: =100-D9 -> 43.810374 | H9: wat_bas_r | I9: =MIN('Data_Estimates-on-the-use-of-wa'!O:O) -> 5.2211369 | J9: =QUARTILE('Data_Estimates-on-the-use-of-wa'!O:O,1) -> 63.354378 | K9: =QUARTILE('Data_Estimates-on-the-use-of-wa'!O:O,3) -> 99.119242 | L9: =MAX('Data_Estimates-on-the-use-of-wa'!O:O) -> 100 | M9: =MODE('Data_Estimates-on-the-use-of-wa'!O:O) -> 100 | N9: =AVERAGE('Data_Estimates-on-the-use-of-wa'!O:O) -> 80.075098 | O9: =K9-J9 -> 35.764864
H10: wat_lim_r | I10: =min('Data_Estimates-on-the-use-of-wa'!P:P) -> 0 | J10: =QUARTILE('Data_Estimates-on-the-use-of-wa'!P:P,1) -> 0 | K10: =QUARTILE('Data_Estimates-on-the-use-of-wa'!P:P,3) -> 8.7545468 | L10: =max('Data_Estimates-on-the-use-of-wa'!P:P) -> 42.164381 | M10: =MODE('Data_Estimates-on-the-use-of-wa'!P:P) -> 0 | N10: =AVERAGE('Data_Estimates-on-the-use-of-wa'!P:P) -> 5.9123163 | O10: =K10-J10 -> 8.7545468
H11: wat_unimp_r | I11: =min('Data_Estimates-on-the-use-of-wa'!Q:Q) -> 0 | J11: =QUARTILE('Data_Estimates-on-the-use-of-wa'!Q:Q,1) -> 0.11567871 | K11: =QUARTILE('Data_Estimates-on-the-use-of-wa'!Q:Q,3) -> 13.266339 | L11: =max('Data_Estimates-on-the-use-of-wa'!Q:Q) -> 51.215982 | M11: =MODE('Data_Estimates-on-the-use-of-wa'!Q:Q) -> 0 | N11: =AVERAGE('Data_Estimates-on-the-use-of-wa'!Q:Q) -> 8.6486528 | O11: =K11-J11 -> 13.150661
H12: wat_sur_r | I12: =min('Data_Estimates-on-the-use-of-wa'!R:R) -> 0 | J12: =quartile('Data_Estimates-on-the-use-of-wa'!R:R,1) -> 0 | K12: =quartile('Data_Estimates-on-the-use-of-wa'!R:R,3) -> 6.6737272 | L12: =max('Data_Estimates-on-the-use-of-wa'!R:R) -> 93.1 | M12: =MODE('Data_Estimates-on-the-use-of-wa'!R:R) -> 0 | N12: =AVERAGE('Data_Estimates-on-the-use-of-wa'!R:R) -> 5.7282994 | O12: =K12-J12 -> 6.6737272
H13: wat_bas_u | I13: =min('Data_Estimates-on-the-use-of-wa'!S:S) -> 0.14354054 | J13: =QUARTILE('Data_Estimates-on-the-use-of-wa'!S:S,1) -> 91.816182 | K13: =QUARTILE('Data_Estimates-on-the-use-of-wa'!S:S,3) -> 99.949418 | L13: =max('Data_Estimates-on-the-use-of-wa'!S:S) -> 100 | M13: =MODE('Data_Estimates-on-the-use-of-wa'!S:S) -> 100 | N13: =AVERAGE('Data_Estimates-on-the-use-of-wa'!S:S) -> 92.83958 | O13: =K13-J13 -> 8.1332356
H14: wat_lim_u | I14: =min('Data_Estimates-on-the-use-of-wa'!T:T) -> 0 | J14: =QUARTILE('Data_Estimates-on-the-use-of-wa'!T:T,1) -> 0 | K14: =QUARTILE('Data_Estimates-on-the-use-of-wa'!T:T,3) -> 3.8226253 | L14: =max('Data_Estimates-on-the-use-of-wa'!T:T) -> 34.27978 | M14: =MODE('Data_Estimates-on-the-use-of-wa'!T:T) -> 0 | N14: =AVERAGE('Data_Estimates-on-the-use-of-wa'!T:T) -> 3.1997842 | O14: =K14-J14 -> 3.8226253
H15: wat_unimp_u | I15: =min('Data_Estimates-on-the-use-of-wa'!U:U) -> 0 | J15: =QUARTILE('Data_Estimates-on-the-use-of-wa'!U:U,1) -> 0 | K15: =QUARTILE('Data_Estimates-on-the-use-of-wa'!U:U,3) -> 1.9704814 | L15: =max('Data_Estimates-on-the-use-of-wa'!U:U) -> 17.722035 | M15: =mode('Data_Estimates-on-the-use-of-wa'!U:U) -> 0 | N15: =AVERAGE('Data_Estimates-on-the-use-of-wa'!U:U) -> 1.5910717 | O15: =K15-J15 -> 1.9704814
H16: wat_sur_u | I16: =min('Data_Estimates-on-the-use-of-wa'!V:V) -> 0 | J16: =QUARTILE('Data_Estimates-on-the-use-of-wa'!V:V,1) -> 0 | K16: =quartile('Data_Estimates-on-the-use-of-wa'!V:V,3) -> 0.15229159 | L16: =max('Data_Estimates-on-the-use-of-wa'!V:V) -> 6.3621605 | M16: =mode('Data_Estimates-on-the-use-of-wa'!V:V) -> 0 | N16: =AVERAGE('Data_Estimates-on-the-use-of-wa'!V:V) -> 0.30325822 | O16: =K16-J16 -> 0.15229159

Sheet Pivot Table 1
A1: 4 | B1: What is the effect of national population size and urbanisation on gross national income and water access?
A2: income_group | B2: SUM of pop_n | C2: AVERAGE of pop_u | D2: AVERAGE of wat_bas_n | E2: AVERAGE of wat_lim_n | F2: AVERAGE of wat_sur_n | G2: AVERAGE of wat_unimp_n
A3: High income | B3: 1212076.1 | C3: 79.355457 | D3: 99.560198 | E3: 0.17690109 | F3: 0.022379721 | G3: 0.24084589
A4: Low income | B4: 590425.16 | C4: 36.044653 | D4: 62.819374 | E4: 16.548388 | F4: 5.4213074 | G4: 15.210931
A5: Lower middle income | B5: 3399310.2 | C5: 48.789904 | D5: 82.210493 | E5: 5.5981366 | F5: 5.8424645 | G5: 7.8386812
A6: NAN | B6: 37264.34 | C6: 61.4605 | D6: 97.181466 | E6: 0.14821981 | F6: 0.32387943 | G6: 2.3869195
A7: Upper middle income | B7: 2547619.3 | C7: 64.905656 | D7: 94.822471 | E7: 1.3247728 | F7: 2.7320684 | G7: 1.4825733
A8: Grand Total | B8: 7786695.1 | C8: 61.938324 | D8: 89.498981 | E8: 3.7892321 | F8: 2.7841715 | G8: 4.4031669
